Workbook

Sheet CIERRE CAJA ENE26
B1: BODEGA 3
B2: CIERRE DE CAJA DIARIO
B3: INGRESOS: | D3: TASA: | E3: 86 | F3: =SUM(F5:F35) -> 2657 | G3: =SUM(G5:G35) -> 0 | H3: =SUM(H5:H35) -> #DIV/0! | I3: =TODAY() -> 46177 | K3: INGRESOS | N3: FORMAS DE PAGO:
A4: ITEM | B4: FECHA | C4: DESCRIPCION | D4: EFECTIVO | E4: PAGO MOVIL | F4: CASH $ | G4: ZELLE | H4: %ING/GAN | I4: TOTAL | K4: DESCRIPCION | L4: MONTO | M4: % | N4: INGRESOS: | O4: $ | P4: Bs
A5: =IF(B5="","",1) -> 1 | B5: 46027 | C5: INGRESO POR VENTAS DESDE EL 01 HASTA EL 03 DE ENERO | F5: 885 | H5: =IF(B5="","",F5/$L$9) -> 0.33308242 | I5: =IF(C5="","",(SUM(D5:E5)/$E$3)+SUM(F5:G5)) -> 885 | J5: =MID(C5,1,8) -> INGRESO | K5: {=UNIQUE($J$5:$J$35,0,0)} -> INGRESO | L5: =SUMIFS($I$5:$I$35,$J$5:$J$35,K5) -> 2657 | M5: =IF(L5=0,"",L5/$L$9) -> 1 | N5: {=TRANSPOSE(D4:G4)} -> EFECTIVO | O5: =D36/$E$3 -> 0 | P5: =D36 -> 0
A6: =IF(B6="","",A5+1) -> 2 | B6: 46034 | C6: INGRESO POR VENTAS DESDE EL 04 HASTA EL 07 DE ENERO | F6: 625 | H6: =IF(B6="","",F6/$L$7) -> #DIV/0! | I6: =IF(C6="","",(SUM(D6:E6)/$E$3)+SUM(F6:G6)) -> 625 | J6: =MID(C6,1,8) -> INGRESO | K6: GANANCIA | L6: =SUMIFS($I$5:$I$35,$J$5:$J$35,K6) -> 0 | M6: =IF(L6=0,"",L6/$L$9) | N6: PAGO MOVIL | O6: =E36/$E$3 -> 0 | P6: =E36 -> 0
A7: =IF(B7="","",A6+1) -> 3 | B7: 46028 | C7: GANANCIA POR TASA CAMBIARIA INVERSIONES DOBLE PICA | H7: =IF(B7="","",F7/$L$7) -> #DIV/0! | I7: =IF(C7="","",(SUM(D7:E7)/$E$3)+SUM(F7:G7)) -> 0 | J7: =MID(C7,1,8) -> GANANCIA | L7: =SUMIFS($I$5:$I$35,$J$5:$J$35,K7) -> 0 | M7: =IF(L7=0,"",L7/$L$9) | N7: CASH $ | O7: =F36 -> 2657
A8: =IF(B8="","",A7+1) | H8: =IF(B8="","",F8/$L$7) | I8: =IF(C8="","",(SUM(D8:E8)/$E$3)+SUM(F8:G8)) | J8: =MID(C8,1,8) | N8: ZELLE | O8: =G36 -> 0
A9: =IF(B9="","",A8+1) | H9: =IF(B9="","",F9/$L$7) | I9: =IF(C9="","",(SUM(D9:E9)/$E$3)+SUM(F9:G9)) | J9: =MID(C9,1,8) | K9: TOTALES: | L9: =SUM(L5:L6) -> 2657 | M9: =SUM(M5:M6) -> 1
A10: =IF(B10="","",A9+1) | H10: =IF(B10="","",F10/$L$7) | I10: =IF(C10="","",(SUM(D10:E10)/$E$3)+SUM(F10:G10)) | J10: =MID(C10,1,8) | O10: =SUM(O5:O9) -> 2657 | P10: =SUM(P5:P9) -> 0
A11: =IF(B11="","",A10+1) -> 1 | B11: 46037 | C11: INGRESO POR VENTAS DESDE EL 08 AL 14 DE ENERO | F11: 1147 | H11: =IF(B11="","",F11/$L$7) -> #DIV/0! | I11: =IF(C11="","",(SUM(D11:E11)/$E$3)+SUM(F11:G11)) -> 1147 | J11: =MID(C11,1,8) -> INGRESO | N11: EGRESOS: | O11: $ | P11: Bs
A12: =IF(B12="","",A11+1) | H12: =IF(B12="","",F12/$L$7) | I12: =IF(C12="","",(SUM(D12:E12)/$E$3)+SUM(F12:G12)) | J12: =MID(C12,1,8) | N12: {=TRANSPOSE(D4:G4)} -> EFECTIVO | O12: =D66/$E$3 -> 0 | P12: =D66 -> 0
A13: =IF(B13="","",A12+1) | H13: =IF(B13="","",F13/$L$7) | I13: =IF(C13="","",(SUM(D13:E13)/$E$3)+SUM(F13:G13)) | J13: =MID(C13,1,8) | N13: PAGO MOVIL | O13: =E66/$E$3 -> 0 | P13: =E66 -> 0
A14: =IF(B14="","",A13+1) | H14: =IF(B14="","",F14/$L$7) | I14: =IF(C14="","",(SUM(D14:E14)/$E$3)+SUM(F14:G14)) | J14: =MID(C14,1,8) | N14: CASH $ | O14: =F66 -> 1003.4
A15: =IF(B15="","",A14+1) | H15: =IF(B15="","",F15/$L$7) | I15: =IF(C15="","",(SUM(D15:E15)/$E$3)+SUM(F15:G15)) | J15: =MID(C15,1,8) | N15: ZELLE | O15: =G66 -> 0
A16: =IF(B16="","",A15+1) | H16: =IF(B16="","",F16/$L$7) | I16: =IF(C16="","",(SUM(D16:E16)/$E$3)+SUM(F16:G16)) | J16: =MID(C16,1,8)
A17: =IF(B17="","",A16+1) | H17: =IF(B17="","",F17/$L$7) | I17: =IF(C17="","",(SUM(D17:E17)/$E$3)+SUM(F17:G17)) | J17: =MID(C17,1,8) | O17: =SUM(O12:O16) -> 1003.4 | P17: =SUM(P12:P16) -> 0
A18: =IF(B18="","",A17+1) | H18: =IF(B18="","",F18/$L$7) | I18: =IF(C18="","",(SUM(D18:E18)/$E$3)+SUM(F18:G18)) | J18: =MID(C18,1,8)
A19: =IF(B19="","",A18+1) | H19: =IF(B19="","",F19/$L$7) | I19: =IF(C19="","",(SUM(D19:E19)/$E$3)+SUM(F19:G19)) | J19: =MID(C19,1,8)
A20: =IF(B20="","",A19+1) | I20: =IF(C20="","",(SUM(D20:E20)/$E$3)+SUM(F20:H20)) | J20: =MID(C20,1,8)
A21: =IF(B21="","",A20+1) | H21: =IF(B21="","",F21/$L$7) | I21: =IF(C21="","",(SUM(D21:E21)/$E$3)+SUM(F21:G21)) | J21: =MID(C21,1,8) | N21: SALDOS AL CIERRE DE CAJA: | Q21: DISTRIBUCION DEL CASH
A22: =IF(B22="","",A21+1) | H22: =IF(B22="","",F22/$L$7) | I22: =IF(C22="","",(SUM(D22:E22)/$E$3)+SUM(F22:G22)) | J22: =MID(C22,1,8) | N22: SDO ANTERIOR: | O22: 0 | R22: 100 | S22: =Q22*R22 -> 0
A23: =IF(B23="","",A22+1) | H23: =IF(B23="","",F23/$L$7) | I23: =IF(C23="","",(SUM(D23:E23)/$E$3)+SUM(F23:G23)) | J23: =MID(C23,1,8) | N23: EFECTIVO | O23: =O5-O12 -> 0 | R23: 50 | S23: =Q23*R23 -> 0
A24: =IF(B24="","",A23+1) | H24: =IF(B24="","",F24/$L$7) | I24: =IF(C24="","",(SUM(D24:E24)/$E$3)+SUM(F24:G24)) | J24: =MID(C24,1,8) | N24: PAGO MOVIL | O24: =O6-O13 -> 0 | R24: 20 | S24: =Q24*R24 -> 0
A25: =IF(B25="","",A24+1) | H25: =IF(B25="","",F25/$L$7) | I25: =IF(C25="","",(SUM(D25:E25)/$E$3)+SUM(F25:G25)) | J25: =MID(C25,1,8) | N25: CASH $ | O25: =O7-O14 -> 1653.6 | R25: 10 | S25: =Q25*R25 -> 0
A26: =IF(B26="","",A25+1) | H26: =IF(B26="","",F26/$L$7) | I26: =IF(C26="","",(SUM(D26:E26)/$E$3)+SUM(F26:G26)) | J26: =MID(C26,1,8) | N26: ZELLE | O26: =O8-O15 -> 0 | R26: 5 | S26: =Q26*R26 -> 0
A27: =IF(B27="","",A26+1) | H27: =IF(B27="","",F27/$L$7) | I27: =IF(C27="","",(SUM(D27:E27)/$E$3)+SUM(F27:G27)) | J27: =MID(C27,1,8) | N27: ORO | O27: =O9-O16 -> 0 | R27: 1 | S27: =Q27*R27 -> 0
A28: =IF(B28="","",A27+1) | H28: =IF(B28="","",F28/$L$7) | I28: =IF(C28="","",(SUM(D28:E28)/$E$3)+SUM(F28:G28)) | J28: =MID(C28,1,8) | N28: TOTAL: | O28: =SUM(O22:O27) -> 1653.6 | Q28: TOTAL: | S28: =SUM(S22:S27) -> 0
A29: =IF(B29="","",A28+1) | H29: =IF(B29="","",F29/$L$7) | I29: =IF(C29="","",(SUM(D29:E29)/$E$3)+SUM(F29:G29)) | J29: =MID(C29,1,8) | Q29: DIFERENCIA: | S29: =S28-O25 -> -1653.6
A30: =IF(B30="","",A29+1) | H30: =IF(B30="","",F30/$L$7) | I30: =IF(C30="","",(SUM(D30:E30)/$E$3)+SUM(F30:G30)) | J30: =MID(C30,1,8)
A31: =IF(B31="","",A30+1) | H31: =IF(B31="","",F31/$L$7) | I31: =IF(C31="","",(SUM(D31:E31)/$E$3)+SUM(F31:G31)) | J31: =MID(C31,1,8)
A32: =IF(B32="","",A31+1) | H32: =IF(B32="","",F32/$L$7) | I32: =IF(C32="","",(SUM(D32:E32)/$E$3)+SUM(F32:G32)) | J32: =MID(C32,1,8)
A33: =IF(B33="","",A32+1) | H33: =IF(B33="","",F33/$L$7) | I33: =IF(C33="","",(SUM(D33:E33)/$E$3)+SUM(F33:G33)) | J33: =MID(C33,1,8)
A34: =IF(B34="","",A33+1) | H34: =IF(B34="","",F34/$L$7) | I34: =IF(C34="","",(SUM(D34:E34)/$E$3)+SUM(F34:G34)) | J34: =MID(C34,1,8)
A35: =IF(B35="","",A34+1) | H35: =IF(B35="","",F35/$L$7) | I35: =IF(C35="","",(SUM(D35:E35)/$E$3)+SUM(F35:G35)) | J35: =MID(C35,1,8)
B36: TOTAL INGRESOS: | D36: =SUM(D5:D35) -> 0 | E36: =SUM(E5:E35) -> 0 | F36: =SUM(F5:F35) -> 2657 | G36: =SUM(G5:G35) -> 0 | H36: =SUM(H5:H35) -> #DIV/0! | I36: =SUM(I5:I35) -> 2657
B37: EGRESOS:
B38: FECHA | C38: DESCRIPCION | D38: EFECTIVO | E38: PAGO MOVIL | F38: CASH $ | G38: ZELLE | H38: ORO | I38: TOTAL
A39: =IF(B39="","",1) -> 1 | B39: 46028 | C39: COMPRA INVERSIONES DOBLE PICA | F39: 753.4 | I39: =F39 -> 753.4 | J39: 19,53*
A40: =IF(B40="","",A39+1) | I40: =F40 | J40: *
...

Sheet CAMBIO DIVISAS
A1: FECHA | B1: DESCRIPCION | C1: PROVEEDOR | D1: MONTO BS | E1: BCV | F1: MONTO | G1: TASA | H1: CAMBIO | I1: GANANCIA | J1: ESTATUS DEL CAMBIO
A2: 45992 | B2: INVERSIONES DOBLE PICA | C2: EXTERNO | D2: 82276.71 | E2: 247.3 | F2: =D2/E2 -> 332.7 | G2: 370 | H2: =D2/G2 -> 222.36949 | I2: =F2-H2 -> 110.33051 | J2: PAGADO
A3: 45992 | B3: TODO ALIMENTOS ORIENTE | C3: EXTERNO | D3: 230235.39 | E3: 247.4 | F3: =D3/E3 -> 930.62001 | G3: 370 | H3: =D3/G3 -> 622.25781 | I3: =F3-H3 -> 308.3622 | J3: PAGADO
A4: 45993 | B4: STARLINK | C4: BERKANA | D4: 0 | E4: 0 | F4: 0 | H4: 150 | I4: 0 | J4: PAGADO
A5: 45995 | B5: HUEVOS Y QUESO | C5: EXTERNO | D5: 66776 | E5: 257.93 | F5: =D5/E5 -> 258.89195 | G5: 411 | H5: 161 | I5: =F5-H5 -> 97.891947 | J5: PAGADO
A6: 45995 | B6: HALLACAS | C6: BERKANA CALLAO | D6: 16824 | E6: 254.92 | F6: =D6/E6 -> 65.997176 | G6: 390 | H6: =D6/G6 -> 43.138462 | I6: =F6-H6 -> 22.858714 | J6: PAGADO
A7: 45999 | B7: REFRESCOS | C7: BERKANA | D7: 5313.16 | E7: 257.92 | F7: =D7/E7 -> 20.600031 | G7: 390 | H7: =D7/G7 -> 13.623487 | I7: =F7-H7 -> 6.9765438 | J7: PAGADO
A8: 45999 | B8: PAN DE JAMON | C8: BERKANA | D8: 16765.5 | E8: 257.92 | F8: =D8/E8 -> 65.002714 | G8: 390 | H8: =D8/G8 -> 42.988462 | I8: =F8-H8 -> 22.014252 | J8: PAGADO
A9: 46001 | B9: HALLACAS | C9: BERKANA CALLAO | D9: 34600 | E9: 262.1 | F9: =D9/E9 -> 132.01068 | G9: 420 | H9: =D9/G9 -> 82.380952 | I9: =F9-H9 -> 49.629731 | J9: PAGADO
A10: 46003 | B10: INVERSIONES DOBLE PICA | C10: EXTERNO | D10: 135197.69 | E10: 267.75 | F10: =D10/E10 -> 504.94002 | G10: 400 | H10: =D10/G10 -> 337.99422 | I10: =F10-H10 -> 166.94579 | J10: PAGADO
A11: 46006 | B11: HALLACAS | C11: BERKANA CALLAO | D11: 18254.28 | E11: 276.58 | F11: =D11/E11 -> 66 | G11: 420 | H11: =D11/G11 -> 43.462571 | I11: =F11-H11 -> 22.537429 | J11: PAGADO
A12: 46009 | B12: HUEVOS | C12: OMAR | D12: 36342.8 | E12: 279.56 | F12: =D12/E12 -> 130 | G12: 420 | H12: =D12/G12 -> 86.530476 | I12: =F12-H12 -> 43.469524 | J12: PAGADO
A13: 46009 | B13: PAN DE JAMON | C13: BERKANA | D13: 17977.7 | E13: 276.58 | F13: =D13/E13 -> 65 | G13: 420 | H13: =D13/G13 -> 42.804048 | I13: =F13-H13 -> 22.195952 | J13: PAGADO
A14: 46013 | B14: HALLACAS | C14: BERKANA | D14: 18265.85 | E14: 285.4 | F14: =D14/E14 -> 64.000876 | G14: 450 | H14: =D14/G14 -> 40.590778 | I14: =F14-H14 -> 23.410098 | J14: PAGADO
A15: 46014 | B15: CESTA | C15: BERKANA | D15: 2307.6 | E15: 288.45 | F15: =D15/E15 -> 8 | G15: 450 | H15: =D15/G15 -> 5.128 | I15: =F15-H15 -> 2.872 | J15: PAGADO
A16: 46014 | B16: BARAKI | C16: EXTERNO | D16: 19107.333 | E16: 288.45 | F16: =D16/E16 -> 66.241405 | G16: 450 | H16: =D16/G16 -> 42.460741 | I16: =F16-H16 -> 23.780664 | J16: PAGADO
A17: 46014 | B17: LA BODEGA | C17: BERKANA | D17: 4182.53 | E17: 288.45 | F17: =D17/E17 -> 14.500017 | G17: 450 | H17: =D17/G17 -> 9.2945111 | I17: =F17-H17 -> 5.2055062 | J17: PAGADO
A18: 46014 | B18: PAPELERIA | C18: BERKANA | D18: 447 | E18: 288.45 | F18: =D18/E18 -> 1.549662 | G18: 450 | H18: =D18/G18 -> 0.99333333 | I18: =F18-H18 -> 0.55632865 | J18: PAGADO
A19: 46015 | B19: POLLO | C19: JONATHAN | F19: 135 | H19: 0 | I19: 0 | J19: PAGADO
A20: 46015 | B20: HUEVOS | C20: OMAR | D20: 37875.5 | E20: 291.35 | F20: =D20/E20 -> 130 | G20: 450 | H20: =D20/G20 -> 84.167778 | I20: =F20-H20 -> 45.832222 | J20: PAGADO
A21: 46017 | B21: DOBLE PICA | C21: DANIEL | D21: 257949.38 | E21: 291.35 | F21: =D21/E21 -> 885.35912 | G21: 470 | H21: =D21/G21 -> 548.82847 | I21: =F21-H21 -> 336.53065 | J21: PAGADO
A22: 46017 | B22: INV. UNARE 3 | C22: DANIEL | D22: =11263.59+16641.92 -> 27905.51 | E22: 291.35 | F22: =D22/E22 -> 95.780024 | G22: 470 | H22: =D22/G22 -> 59.373426 | I22: =F22-H22 -> 36.406598 | J22: PAGADO
A23: 46020 | B23: HALLACAS | C23: BERKANA | D23: 28317.84 | E23: 294.963 | F23: =D23/E23 -> 96.004719 | G23: 485 | H23: =D23/G23 -> 58.387299 | I23: =F23-H23 -> 37.61742 | J23: PAGADO
A24: 46386 | B24: HALLACAS | C24: EXTERNO | D24: 29814.3 | E24: 298.14 | F24: =D24/E24 -> 100.00101 | G24: 505 | H24: =D24/G24 -> 59.038218 | I24: =F24-H24 -> 40.962788 | J24: PAGADO
A25: 46386 | B25: PAN DE JAMON | C25: EXTERNO | D25: 29497 | E25: 294.969 | F25: =D25/E25 -> 100.00034 | G25: 500 | H25: =D25/G25 -> 58.994 | I25: =F25-H25 -> 41.006339 | J25: PAGADO
A26: 46028 | B26: DOBLE PICA | C26: EXTERNO | D26: 232160.89 | E26: 308.15 | F26: =D26/E26 -> 753.40221 | G26: 550 | H26: =D26/G26 -> 422.11071 | I26: =F26-H26 -> 331.2915 | J26: PAGADO
A27: 46028 | B27: INV. UNARE 3 | C27: EXTERNO | D27: 13537.03 | E27: 308.15 | F27: =D27/E27 -> 43.930002 | G27: 550 | H27: =D27/G27 -> 24.612782 | I27: =F27-H27 -> 19.31722 | J27: PAGADO
A28: 46035 | B28: DOBLE PICA | C28: BERKANA | D28: 190252.62 | E28: 330.38 | F28: =D28/E28 -> 575.85998 | G28: 520 | H28: =D28/G28 -> 365.87042 | I28: =F28-H28 -> 209.98956 | J28: PENDIENTE
A29: 46035 | B29: FARMACIA EL FORTIN | C29: EXTERNO | D29: 61570.26 | E29: 330.38 | F29: =D29/E29 -> 186.36195 | G29: 520 | H29: =D29/G29 -> 118.40435 | I29: =F29-H29 -> 67.957601 | J29: PENDIENTE
A30: 46035 | B30: COMERCIAL ALBAVEN | C30: EXTERNO | D30: 9795.77 | E30: 330.38 | F30: =D30/E30 -> 29.650009 | G30: 520 | H30: =D30/G30 -> 18.838019 | I30: =F30-H30 -> 10.81199 | J30: PENDIENTE
F31: =D31/E31 -> #DIV/0! | H31: =D31/G31 -> #DIV/0! | I31: =F31-H31 -> #DIV/0!
F32: =D32/E32 -> #DIV/0! | H32: =D32/G32 -> #DIV/0! | I32: =F32-H32 -> #DIV/0!
F33: =D33/E33 -> #DIV/0! | H33: =D33/G33 -> #DIV/0! | I33: =F33-H33 -> #DIV/0!
F34: =D34/E34 -> #DIV/0! | H34: =D34/G34 -> #DIV/0! | I34: =F34-H34 -> #DIV/0!
F35: =D35/E35 -> #DIV/0! | H35: =D35/G35 -> #DIV/0! | I35: =F35-H35 -> #DIV/0!
F36: =D36/E36 -> #DIV/0! | H36: =D36/G36 -> #DIV/0! | I36: =F36-H36 -> #DIV/0!
F37: =D37/E37 -> #DIV/0! | H37: =D37/G37 -> #DIV/0! | I37: =F37-H37 -> #DIV/0!
F38: =D38/E38 -> #DIV/0! | H38: =D38/G38 -> #DIV/0! | I38: =F38-H38 -> #DIV/0!

Sheet VENTAS
B1: BODEGA3 | O1: BODEGA3
F2: VENTAS $ | I2: VENTAS Bs. | L2: TOTAL $ | S2: TOTALES
F3: =SUM(F5:F14000) -> 2485.1 | H3: =SUM(H5:H14000) -> 3066.2374 | K3: =SUM(K5:K14000) -> 0 | L3: =SUM(L5:L14000) -> 3066.2374 | O3: 46024 | S3: =SUM(S5:S14000) -> 237.85 | U3: =SUM(U5:U14000) -> 361.4987
B4: FECHA | C4: CLIENTE | D4: PRODUCTO | E4: COD/PROD | F4: CANT | G4: PRECIO/UNIT $ | H4: MONTO/TOTAL | I4: PRECIO UNIT Bs | J4: TASA | K4: TOTAL Bs | L4: MONTO TOTAL $ | O4: FECHA | P4: CLIENTE | Q4: PRODUCTO | R4: COD/PROD | S4: CANT | T4: PRECIO/UNIT | U4: MONTO/TOTAL
B5: 46023 | C5: CONSUMIDOR FINAL | D5: Belmont | E5: {=IF(D5="","",XLOOKUP(D5,DATOS!$D$6:D14000,DATOS!$C$6:C14000,0,0,1))} -> BELM | F5: 8 | G5: 0.25 | H5: =IF(F5="","",(F5*G5)) -> 2 | K5: =IF(I5="","",(F5*I5)) | L5: =IF(I5="",H5,H5+(K5/J5)) -> 2 | O5: =IFERROR(__xludf.DUMMYFUNCTION("FILTER(B5:J14000,B5:B14000=O3)"),46024.0) -> 46024 | P5: =IFERROR(__xludf.DUMMYFUNCTION("""COMPUTED_VALUE"""),"CONSUMIDOR FINAL") -> CONSUMIDOR FINAL | Q5: =IFERROR(__xludf.DUMMYFUNCTION("""COMPUTED_VALUE"""),"Huevo") -> Huevo | R5: =IFERROR(__xludf.DUMMYFUNCTION("""COMPUTED_VALUE"""),"HUEVO") -> HUEVO | S5: =IFERROR(__xludf.DUMMYFUNCTION("""COMPUTED_VALUE"""),15.0) -> 15 | T5: =IFERROR(__xludf.DUMMYFUNCTION("""COMPUTED_VALUE"""),0.3333) -> 0.3333 | U5: =IFERROR(__xludf.DUMMYFUNCTION("""COMPUTED_VALUE"""),4.999499999999999) -> 4.9995
B6: 46023 | C6: CONSUMIDOR FINAL | D6: HALLACAS | E6: {=IF(D6="","",XLOOKUP(D6,DATOS!$D$6:D14000,DATOS!$C$6:C14000,0,0,1))} -> 00050 | F6: 2 | G6: 4.5 | H6: =IF(F6="","",(F6*G6)) -> 9 | K6: =IF(I6="","",(F6*I6)) | L6: =IF(I6="",H6,H6+(K6/J6)) -> 9 | O6: =IFERROR(__xludf.DUMMYFUNCTION("""COMPUTED_VALUE"""),46024.0) -> 46024 | P6: =IFERROR(__xludf.DUMMYFUNCTION("""COMPUTED_VALUE"""),"CONSUMIDOR FINAL") -> CONSUMIDOR FINAL | Q6: =IFERROR(__xludf.DUMMYFUNCTION("""COMPUTED_VALUE"""),"Caramelos Bianchi") -> Caramelos Bianchi | R6: =IFERROR(__xludf.DUMMYFUNCTION("""COMPUTED_VALUE"""),"CARM2") -> CARM2 | S6: =IFERROR(__xludf.DUMMYFUNCTION("""COMPUTED_VALUE"""),5.0) -> 5 | T6: =IFERROR(__xludf.DUMMYFUNCTION("""COMPUTED_VALUE"""),0.1) -> 0.1 | U6: =IFERROR(__xludf.DUMMYFUNCTION("""COMPUTED_VALUE"""),0.5) -> 0.5
B7: 46023 | C7: CONSUMIDOR FINAL | D7: Refrescos 1lt | E7: {=IF(D7="","",XLOOKUP(D7,DATOS!$D$6:D14000,DATOS!$C$6:C14000,0,0,1))} -> REF3 | F7: 1 | G7: 3 | H7: =IF(F7="","",(F7*G7)) -> 3 | K7: =IF(I7="","",(F7*I7)) | L7: =IF(I7="",H7,H7+(K7/J7)) -> 3 | O7: =IFERROR(__xludf.DUMMYFUNCTION("""COMPUTED_VALUE"""),46024.0) -> 46024 | P7: =IFERROR(__xludf.DUMMYFUNCTION("""COMPUTED_VALUE"""),"CONSUMIDOR FINAL") -> CONSUMIDOR FINAL | Q7: =IFERROR(__xludf.DUMMYFUNCTION("""COMPUTED_VALUE"""),"CARAMELOS FRUTICAS 100UND") -> CARAMELOS FRUTICAS 100UND | R7: =IFERROR(__xludf.DUMMYFUNCTION("""COMPUTED_VALUE"""),"CARM005") -> CARM005 | S7: =IFERROR(__xludf.DUMMYFUNCTION("""COMPUTED_VALUE"""),5.0) -> 5 | T7: =IFERROR(__xludf.DUMMYFUNCTION("""COMPUTED_VALUE"""),0.1) -> 0.1 | U7: =IFERROR(__xludf.DUMMYFUNCTION("""COMPUTED_VALUE"""),0.5) -> 0.5
B8: 46023 | C8: CONSUMIDOR FINAL | D8: galleta marilu chocolate | E8: {=IF(D8="","",XLOOKUP(D8,DATOS!$D$6:D14000,DATOS!$C$6:C14000,0,0,1))} -> 00017 | F8: 2 | G8: 0.5 | H8: =IF(F8="","",(F8*G8)) -> 1 | K8: =IF(I8="","",(F8*I8)) | L8: =IF(I8="",H8,H8+(K8/J8)) -> 1 | O8: =IFERROR(__xludf.DUMMYFUNCTION("""COMPUTED_VALUE"""),46024.0) -> 46024 | P8: =IFERROR(__xludf.DUMMYFUNCTION("""COMPUTED_VALUE"""),"CONSUMIDOR FINAL") -> CONSUMIDOR FINAL | Q8: =IFERROR(__xludf.DUMMYFUNCTION("""COMPUTED_VALUE"""),"Huevo") -> Huevo | R8: =IFERROR(__xludf.DUMMYFUNCTION("""COMPUTED_VALUE"""),"HUEVO") -> HUEVO | S8: =IFERROR(__xludf.DUMMYFUNCTION("""COMPUTED_VALUE"""),12.0) -> 12 | T8: =IFERROR(__xludf.DUMMYFUNCTION("""COMPUTED_VALUE"""),0.3333) -> 0.3333 | U8: =IFERROR(__xludf.DUMMYFUNCTION("""COMPUTED_VALUE"""),3.9996) -> 3.9996
B9: 46023 | C9: CONSUMIDOR FINAL | D9: Pollo 1kg | E9: {=IF(D9="","",XLOOKUP(D9,DATOS!$D$6:D14000,DATOS!$C$6:C14000,0,0,1))} -> POLLO | F9: 3.25 | G9: 5 | H9: =IF(F9="","",(F9*G9)) -> 16.25 | K9: =IF(I9="","",(F9*I9)) | L9: =IF(I9="",H9,H9+(K9/J9)) -> 16.25 | O9: =IFERROR(__xludf.DUMMYFUNCTION("""COMPUTED_VALUE"""),46024.0) -> 46024 | P9: =IFERROR(__xludf.DUMMYFUNCTION("""COMPUTED_VALUE"""),"CONSUMIDOR FINAL") -> CONSUMIDOR FINAL | Q9: =IFERROR(__xludf.DUMMYFUNCTION("""COMPUTED_VALUE"""),"GALLETA MARILU CHOCOVAINILLA") -> GALLETA MARILU CHOCOVAINILLA | R9: =IFERROR(__xludf.DUMMYFUNCTION("""COMPUTED_VALUE"""),"GALL024") -> GALL024 | S9: =IFERROR(__xludf.DUMMYFUNCTION("""COMPUTED_VALUE"""),2.0) -> 2 | T9: =IFERROR(__xludf.DUMMYFUNCTION("""COMPUTED_VALUE"""),0.5) -> 0.5 | U9: =IFERROR(__xludf.DUMMYFUNCTION("""COMPUTED_VALUE"""),1.0) -> 1
B10: 46023 | C10: CONSUMIDOR FINAL | D10: BIG BOG SABORES VARIADOS | E10: {=IF(D10="","",XLOOKUP(D10,DATOS!$D$6:D14000,DATOS!$C$6:C14000,0,0,1))} -> 00081 | F10: 2 | G10: 0.5 | H10: =IF(F10="","",(F10*G10)) -> 1 | K10: =IF(I10="","",(F10*I10)) | L10: =IF(I10="",H10,H10+(K10/J10)) -> 1 | O10: =IFERROR(__xludf.DUMMYFUNCTION("""COMPUTED_VALUE"""),46024.0) -> 46024 | P10: =IFERROR(__xludf.DUMMYFUNCTION("""COMPUTED_VALUE"""),"CONSUMIDOR FINAL") -> CONSUMIDOR FINAL | Q10: =IFERROR(__xludf.DUMMYFUNCTION("""COMPUTED_VALUE"""),"Huevo") -> Huevo | R10: =IFERROR(__xludf.DUMMYFUNCTION("""COMPUTED_VALUE"""),"HUEVO") -> HUEVO | S10: =IFERROR(__xludf.DUMMYFUNCTION("""COMPUTED_VALUE"""),6.0) -> 6 | T10: =IFERROR(__xludf.DUMMYFUNCTION("""COMPUTED_VALUE"""),0.333333) -> 0.333333 | U10: =IFERROR(__xludf.DUMMYFUNCTION("""COMPUTED_VALUE"""),1.999998) -> 1.999998
B11: 46023 | C11: CONSUMIDOR FINAL | D11: CARAMELOS FRUTICAS 100UND | E11: {=IF(D11="","",XLOOKUP(D11,DATOS!$D$6:D14000,DATOS!$C$6:C14000,0,0,1))} -> CARM005 | F11: 10 | G11: 0.1 | H11: =IF(F11="","",(F11*G11)) -> 1 | K11: =IF(I11="","",(F11*I11)) | L11: =IF(I11="",H11,H11+(K11/J11)) -> 1 | O11: =IFERROR(__xludf.DUMMYFUNCTION("""COMPUTED_VALUE"""),46024.0) -> 46024 | P11: =IFERROR(__xludf.DUMMYFUNCTION("""COMPUTED_VALUE"""),"CONSUMIDOR FINAL") -> CONSUMIDOR FINAL | Q11: =IFERROR(__xludf.DUMMYFUNCTION("""COMPUTED_VALUE"""),"Arroz Mary tradicional tipo 1 900g") -> Arroz Mary tradicional tipo 1 900g | R11: =IFERROR(__xludf.DUMMYFUNCTION("""COMPUTED_VALUE"""),"AR1") -> AR1 | S11: =IFERROR(__xludf.DUMMYFUNCTION("""COMPUTED_VALUE"""),1.0) -> 1 | T11: =IFERROR(__xludf.DUMMYFUNCTION("""COMPUTED_VALUE"""),2.5) -> 2.5 | U11: =IFERROR(__xludf.DUMMYFUNCTION("""COMPUTED_VALUE"""),2.5) -> 2.5
B12: 46023 | C12: CONSUMIDOR FINAL | D12: Caramelos Bianchi | E12: {=IF(D12="","",XLOOKUP(D12,DATOS!$D$6:D14000,DATOS!$C$6:C14000,0,0,1))} -> CARM2 | F12: 10 | G12: 0.1 | H12: =IF(F12="","",(F12*G12)) -> 1 | K12: =IF(I12="","",(F12*I12)) | L12: =IF(I12="",H12,H12+(K12/J12)) -> 1 | O12: =IFERROR(__xludf.DUMMYFUNCTION("""COMPUTED_VALUE"""),46024.0) -> 46024 | P12: =IFERROR(__xludf.DUMMYFUNCTION("""COMPUTED_VALUE"""),"CONSUMIDOR FINAL") -> CONSUMIDOR FINAL | Q12: =IFERROR(__xludf.DUMMYFUNCTION("""COMPUTED_VALUE"""),"Cubitos") -> Cubitos | R12: =IFERROR(__xludf.DUMMYFUNCTION("""COMPUTED_VALUE"""),"CUBITO1") -> CUBITO1 | S12: =IFERROR(__xludf.DUMMYFUNCTION("""COMPUTED_VALUE"""),3.0) -> 3 | T12: =IFERROR(__xludf.DUMMYFUNCTION("""COMPUTED_VALUE"""),0.5) -> 0.5 | U12: =IFERROR(__xludf.DUMMYFUNCTION("""COMPUTED_VALUE"""),1.5) -> 1.5
B13: 46023 | C13: CONSUMIDOR FINAL | D13: Caramelos Chao | E13: {=IF(D13="","",XLOOKUP(D13,DATOS!$D$6:D14000,DATOS!$C$6:C14000,0,0,1))} -> CARM4 | F13: 10 | G13: 0.1 | H13: =IF(F13="","",(F13*G13)) -> 1 | K13: =IF(I13="","",(F13*I13)) | L13: =IF(I13="",H13,H13+(K13/J13)) -> 1 | O13: =IFERROR(__xludf.DUMMYFUNCTION("""COMPUTED_VALUE"""),46024.0) -> 46024 | P13: =IFERROR(__xludf.DUMMYFUNCTION("""COMPUTED_VALUE"""),"CONSUMIDOR FINAL") -> CONSUMIDOR FINAL | Q13: =IFERROR(__xludf.DUMMYFUNCTION("""COMPUTED_VALUE"""),"PAPEL HIGIENICO MARRON ") -> PAPEL HIGIENICO MARRON | R13: =IFERROR(__xludf.DUMMYFUNCTION("""COMPUTED_VALUE"""),"00097") -> 00097 | S13: =IFERROR(__xludf.DUMMYFUNCTION("""COMPUTED_VALUE"""),1.0) -> 1 | T13: =IFERROR(__xludf.DUMMYFUNCTION("""COMPUTED_VALUE"""),2.0) -> 2 | U13: =IFERROR(__xludf.DUMMYFUNCTION("""COMPUTED_VALUE"""),2.0) -> 2
B14: 46023 | C14: CONSUMIDOR FINAL | D14: Belmont | E14: {=IF(D14="","",XLOOKUP(D14,DATOS!$D$6:D14000,DATOS!$C$6:C14000,0,0,1))} -> BELM | F14: 20 | G14: 0.25 | H14: =IF(F14="","",(F14*G14)) -> 5 | K14: =IF(I14="","",(F14*I14)) | L14: =IF(I14="",H14,H14+(K14/J14)) -> 5 | O14: =IFERROR(__xludf.DUMMYFUNCTION("""COMPUTED_VALUE"""),46024.0) -> 46024 | P14: =IFERROR(__xludf.DUMMYFUNCTION("""COMPUTED_VALUE"""),"CONSUMIDOR FINAL") -> CONSUMIDOR FINAL | Q14: =IFERROR(__xludf.DUMMYFUNCTION("""COMPUTED_VALUE"""),"Jabon las llaves floral (200gr)") -> Jabon las llaves floral (200gr) | R14: =IFERROR(__xludf.DUMMYFUNCTION("""COMPUTED_VALUE"""),"00029") -> 00029 | S14: =IFERROR(__xludf.DUMMYFUNCTION("""COMPUTED_VALUE"""),1.0) -> 1 | T14: =IFERROR(__xludf.DUMMYFUNCTION("""COMPUTED_VALUE"""),2.0) -> 2 | U14: =IFERROR(__xludf.DUMMYFUNCTION("""COMPUTED_VALUE"""),2.0) -> 2
B15: 46023 | C15: CONSUMIDOR FINAL | D15: CARAMELOS FRUTICAS 100UND | E15: {=IF(D15="","",XLOOKUP(D15,DATOS!$D$6:D14000,DATOS!$C$6:C14000,0,0,1))} -> CARM005 | F15: 10 | G15: 0.1 | H15: =IF(F15="","",(F15*G15)) -> 1 | K15: =IF(I15="","",(F15*I15)) | L15: =IF(I15="",H15,H15+(K15/J15)) -> 1 | O15: =IFERROR(__xludf.DUMMYFUNCTION("""COMPUTED_VALUE"""),46024.0) -> 46024 | P15: =IFERROR(__xludf.DUMMYFUNCTION("""COMPUTED_VALUE"""),"CONSUMIDOR FINAL") -> CONSUMIDOR FINAL | Q15: =IFERROR(__xludf.DUMMYFUNCTION("""COMPUTED_VALUE"""),"MARGARINA MAVESA 250GR") -> MARGARINA MAVESA 250GR | R15: =IFERROR(__xludf.DUMMYFUNCTION("""COMPUTED_VALUE"""),"MARG1") -> MARG1 | S15: =IFERROR(__xludf.DUMMYFUNCTION("""COMPUTED_VALUE"""),1.0) -> 1 | T15: =IFERROR(__xludf.DUMMYFUNCTION("""COMPUTED_VALUE"""),3.0) -> 3 | U15: =IFERROR(__xludf.DUMMYFUNCTION("""COMPUTED_VALUE"""),3.0) -> 3
B16: 46023 | C16: CONSUMIDOR FINAL | D16: Queso duro | E16: {=IF(D16="","",XLOOKUP(D16,DATOS!$D$6:D14000,DATOS!$C$6:C14000,0,0,1))} -> QUES1 | F16: 0.2 | G16: 10 | H16: =IF(F16="","",(F16*G16)) -> 2 | K16: =IF(I16="","",(F16*I16)) | L16: =IF(I16="",H16,H16+(K16/J16)) -> 2 | O16: =IFERROR(__xludf.DUMMYFUNCTION("""COMPUTED_VALUE"""),46024.0) -> 46024 | P16: =IFERROR(__xludf.DUMMYFUNCTION("""COMPUTED_VALUE"""),"CONSUMIDOR FINAL") -> CONSUMIDOR FINAL | Q16: =IFERROR(__xludf.DUMMYFUNCTION("""COMPUTED_VALUE"""),"Queso duro") -> Queso duro | R16: =IFERROR(__xludf.DUMMYFUNCTION("""COMPUTED_VALUE"""),"QUES1") -> QUES1 | S16: =IFERROR(__xludf.DUMMYFUNCTION("""COMPUTED_VALUE"""),0.2) -> 0.2 | T16: =IFERROR(__xludf.DUMMYFUNCTION("""COMPUTED_VALUE"""),10.0) -> 10 | U16: =IFERROR(__xludf.DUMMYFUNCTION("""COMPUTED_VALUE"""),2.0) -> 2
B17: 46023 | C17: CONSUMIDOR FINAL | D17: Pollo 1kg | E17: {=IF(D17="","",XLOOKUP(D17,DATOS!$D$6:D14000,DATOS!$C$6:C14000,0,0,1))} -> POLLO | F17: 2.75 | G17: 5 | H17: =IF(F17="","",(F17*G17)) -> 13.75 | K17: =IF(I17="","",(F17*I17)) | L17: =IF(I17="",H17,H17+(K17/J17)) -> 13.75 | O17: =IFERROR(__xludf.DUMMYFUNCTION("""COMPUTED_VALUE"""),46024.0) -> 46024 | P17: =IFERROR(__xludf.DUMMYFUNCTION("""COMPUTED_VALUE"""),"CONSUMIDOR FINAL") -> CONSUMIDOR FINAL | Q17: =IFERROR(__xludf.DUMMYFUNCTION("""COMPUTED_VALUE"""),"Huevo") -> Huevo | R17: =IFERROR(__xludf.DUMMYFUNCTION("""COMPUTED_VALUE"""),"HUEVO") -> HUEVO | S17: =IFERROR(__xludf.DUMMYFUNCTION("""COMPUTED_VALUE"""),6.0) -> 6 | T17: =IFERROR(__xludf.DUMMYFUNCTION("""COMPUTED_VALUE"""),0.3333) -> 0.3333 | U17: =IFERROR(__xludf.DUMMYFUNCTION("""COMPUTED_VALUE"""),1.9998) -> 1.9998
B18: 46023 | C18: CONSUMIDOR FINAL | D18: ATUN PEÑERO OLIVA VERDE | E18: {=IF(D18="","",XLOOKUP(D18,DATOS!$D$6:D14000,DATOS!$C$6:C14000,0,0,1))} -> 00116 | F18: 1 | G18: 3.5 | H18: =IF(F18="","",(F18*G18)) -> 3.5 | K18: =IF(I18="","",(F18*I18)) | L18: =IF(I18="",H18,H18+(K18/J18)) -> 3.5 | O18: =IFERROR(__xludf.DUMMYFUNCTION("""COMPUTED_VALUE"""),46024.0) -> 46024 | P18: =IFERROR(__xludf.DUMMYFUNCTION("""COMPUTED_VALUE"""),"CONSUMIDOR FINAL") -> CONSUMIDOR FINAL | Q18: =IFERROR(__xludf.DUMMYFUNCTION("""COMPUTED_VALUE"""),"GALLETA MARILU CHOCOVAINILLA") -> GALLETA MARILU CHOCOVAINILLA | R18: =IFERROR(__xludf.DUMMYFUNCTION("""COMPUTED_VALUE"""),"GALL024") -> GALL024 | S18: =IFERROR(__xludf.DUMMYFUNCTION("""COMPUTED_VALUE"""),2.0) -> 2 | T18: =IFERROR(__xludf.DUMMYFUNCTION("""COMPUTED_VALUE"""),0.5) -> 0.5 | U18: =IFERROR(__xludf.DUMMYFUNCTION("""COMPUTED_VALUE"""),1.0) -> 1
B19: 46023 | C19: CONSUMIDOR FINAL | D19: CARAMELOS FRUTICAS 100UND | E19: {=IF(D19="","",XLOOKUP(D19,DATOS!$D$6:D14000,DATOS!$C$6:C14000,0,0,1))} -> CARM005 | F19: 5 | G19: 0.1 | H19: =IF(F19="","",(F19*G19)) -> 0.5 | K19: =IF(I19="","",(F19*I19)) | L19: =IF(I19="",H19,H19+(K19/J19)) -> 0.5 | O19: =IFERROR(__xludf.DUMMYFUNCTION("""COMPUTED_VALUE"""),46024.0) -> 46024 | P19: =IFERROR(__xludf.DUMMYFUNCTION("""COMPUTED_VALUE"""),"CONSUMIDOR FINAL") -> CONSUMIDOR FINAL | Q19: =IFERROR(__xludf.DUMMYFUNCTION("""COMPUTED_VALUE"""),"Huevo") -> Huevo | R19: =IFERROR(__xludf.DUMMYFUNCTION("""COMPUTED_VALUE"""),"HUEVO") -> HUEVO | S19: =IFERROR(__xludf.DUMMYFUNCTION("""COMPUTED_VALUE"""),18.0) -> 18 | T19: =IFERROR(__xludf.DUMMYFUNCTION("""COMPUTED_VALUE"""),0.33333) -> 0.33333 | U19: =IFERROR(__xludf.DUMMYFUNCTION("""COMPUTED_VALUE"""),5.9999400000000005) -> 5.99994
B20: 46023 | C20: CONSUMIDOR FINAL | D20: Huevo | E20: {=IF(D20="","",XLOOKUP(D20,DATOS!$D$6:D14000,DATOS!$C$6:C14000,0,0,1))} -> HUEVO | F20: 3 | G20: 0.3333 | H20: =IF(F20="","",(F20*G20)) -> 0.9999 | K20: =IF(I20="","",(F20*I20)) | L20: =IF(I20="",H20,H20+(K20/J20)) -> 0.9999 | O20: =IFERROR(__xludf.DUMMYFUNCTION("""COMPUTED_VALUE"""),46024.0) -> 46024 | P20: =IFERROR(__xludf.DUMMYFUNCTION("""COMPUTED_VALUE"""),"CONSUMIDOR FINAL") -> CONSUMIDOR FINAL | Q20: =IFERROR(__xludf.DUMMYFUNCTION("""COMPUTED_VALUE"""),"Queso duro") -> Queso duro | R20: =IFERROR(__xludf.DUMMYFUNCTION("""COMPUTED_VALUE"""),"QUES1") -> QUES1 | S20: =IFERROR(__xludf.DUMMYFUNCTION("""COMPUTED_VALUE"""),0.25) -> 0.25 | T20: =IFERROR(__xludf.DUMMYFUNCTION("""COMPUTED_VALUE"""),10.0) -> 10 | U20: =IFERROR(__xludf.DUMMYFUNCTION("""COMPUTED_VALUE"""),2.5) -> 2.5
B21: 46023 | C21: CONSUMIDOR FINAL | D21: Panelada 29gr | E21: {=IF(D21="","",XLOOKUP(D21,DATOS!$D$6:D14000,DATOS!$C$6:C14000,0,0,1))} -> PANEL | F21: 1 | G21: 1 | H21: =IF(F21="","",(F21*G21)) -> 1 | K21: =IF(I21="","",(F21*I21)) | L21: =IF(I21="",H21,H21+(K21/J21)) -> 1 | O21: =IFERROR(__xludf.DUMMYFUNCTION("""COMPUTED_VALUE"""),46024.0) -> 46024 | P21: =IFERROR(__xludf.DUMMYFUNCTION("""COMPUTED_VALUE"""),"CONSUMIDOR FINAL") -> CONSUMIDOR FINAL | Q21: =IFERROR(__xludf.DUMMYFUNCTION("""COMPUTED_VALUE"""),"BIG BOG SABORES VARIADOS") -> BIG BOG SABORES VARIADOS | R21: =IFERROR(__xludf.DUMMYFUNCTION("""COMPUTED_VALUE"""),"00081") -> 00081 | S21: =IFERROR(__xludf.DUMMYFUNCTION("""COMPUTED_VALUE"""),1.0) -> 1 | T21: =IFERROR(__xludf.DUMMYFUNCTION("""COMPUTED_VALUE"""),0.5) -> 0.5 | U21: =IFERROR(__xludf.DUMMYFUNCTION("""COMPUTED_VALUE"""),0.5) -> 0.5
B22: 46023 | C22: CONSUMIDOR FINAL | D22: Refrescos 2lt | E22: {=IF(D22="","",XLOOKUP(D22,DATOS!$D$6:D14000,DATOS!$C$6:C14000,0,0,1))} -> REF4 | F22: 1 | G22: 6 | H22: =IF(F22="","",(F22*G22)) -> 6 | K22: =IF(I22="","",(F22*I22)) | L22: =IF(I22="",H22,H22+(K22/J22)) -> 6 | O22: =IFERROR(__xludf.DUMMYFUNCTION("""COMPUTED_VALUE"""),46024.0) -> 46024 | P22: =IFERROR(__xludf.DUMMYFUNCTION("""COMPUTED_VALUE"""),"CONSUMIDOR FINAL") -> CONSUMIDOR FINAL | Q22: =IFERROR(__xludf.DUMMYFUNCTION("""COMPUTED_VALUE"""),"Huevo") -> Huevo | R22: =IFERROR(__xludf.DUMMYFUNCTION("""COMPUTED_VALUE"""),"HUEVO") -> HUEVO | S22: =IFERROR(__xludf.DUMMYFUNCTION("""COMPUTED_VALUE"""),9.0) -> 9 | T22: =IFERROR(__xludf.DUMMYFUNCTION("""COMPUTED_VALUE"""),0.33333333) -> 0.33333333 | U22: =IFERROR(__xludf.DUMMYFUNCTION("""COMPUTED_VALUE"""),2.9999999699999997) -> 3
B23: 46023 | C23: CONSUMIDOR FINAL | D23: caramelo trululu aros 100UND | E23: {=IF(D23="","",XLOOKUP(D23,DATOS!$D$6:D14000,DATOS!$C$6:C14000,0,0,1))} -> 00010 | F23: 10 | G23: 0.1 | H23: =IF(F23="","",(F23*G23)) -> 1 | K23: =IF(I23="","",(F23*I23)) | L23: =IF(I23="",H23,H23+(K23/J23)) -> 1 | O23: =IFERROR(__xludf.DUMMYFUNCTION("""COMPUTED_VALUE"""),46024.0) -> 46024 | P23: =IFERROR(__xludf.DUMMYFUNCTION("""COMPUTED_VALUE"""),"CONSUMIDOR FINAL") -> CONSUMIDOR FINAL | Q23: =IFERROR(__xludf.DUMMYFUNCTION("""COMPUTED_VALUE"""),"BIG BOG SABORES VARIADOS") -> BIG BOG SABORES VARIADOS | R23: =IFERROR(__xludf.DUMMYFUNCTION("""COMPUTED_VALUE"""),"00081") -> 00081 | S23: =IFERROR(__xludf.DUMMYFUNCTION("""COMPUTED_VALUE"""),2.0) -> 2 | T23: =IFERROR(__xludf.DUMMYFUNCTION("""COMPUTED_VALUE"""),0.5) -> 0.5 | U23: =IFERROR(__xludf.DUMMYFUNCTION("""COMPUTED_VALUE"""),1.0) -> 1
B24: 46023 | C24: CONSUMIDOR FINAL | D24: PAPEL HIGIENICO MARRON | E24: {=IF(D24="","",XLOOKUP(D24,DATOS!$D$6:D14000,DATOS!$C$6:C14000,0,0,1))} -> 00097 | F24: 2 | G24: 2 | H24: =IF(F24="","",(F24*G24)) -> 4 | K24: =IF(I24="","",(F24*I24)) | L24: =IF(I24="",H24,H24+(K24/J24)) -> 4 | O24: =IFERROR(__xludf.DUMMYFUNCTION("""COMPUTED_VALUE"""),46024.0) -> 46024 | P24: =IFERROR(__xludf.DUMMYFUNCTION("""COMPUTED_VALUE"""),"CONSUMIDOR FINAL") -> CONSUMIDOR FINAL | Q24: =IFERROR(__xludf.DUMMYFUNCTION("""COMPUTED_VALUE"""),"Queso duro") -> Queso duro | R24: =IFERROR(__xludf.DUMMYFUNCTION("""COMPUTED_VALUE"""),"QUES1") -> QUES1 | S24: =IFERROR(__xludf.DUMMYFUNCTION("""COMPUTED_VALUE"""),0.2) -> 0.2 | T24: =IFERROR(__xludf.DUMMYFUNCTION("""COMPUTED_VALUE"""),10.0) -> 10 | U24: =IFERROR(__xludf.DUMMYFUNCTION("""COMPUTED_VALUE"""),2.0) -> 2
B25: 46023 | C25: CONSUMIDOR FINAL | D25: galleta marilu chocolate | E25: {=IF(D25="","",XLOOKUP(D25,DATOS!$D$6:D14000,DATOS!$C$6:C14000,0,0,1))} -> 00017 | F25: 2 | G25: 0.5 | H25: =IF(F25="","",(F25*G25)) -> 1 | K25: =IF(I25="","",(F25*I25)) | L25: =IF(I25="",H25,H25+(K25/J25)) -> 1 | O25: =IFERROR(__xludf.DUMMYFUNCTION("""COMPUTED_VALUE"""),46024.0) -> 46024 | P25: =IFERROR(__xludf.DUMMYFUNCTION("""COMPUTED_VALUE"""),"CONSUMIDOR FINAL") -> CONSUMIDOR FINAL | Q25: =IFERROR(__xludf.DUMMYFUNCTION("""COMPUTED_VALUE"""),"MARGARINA MAVESA 500GR") -> MARGARINA MAVESA 500GR | R25: =IFERROR(__xludf.DUMMYFUNCTION("""COMPUTED_VALUE"""),"MARG2") -> MARG2 | S25: =IFERROR(__xludf.DUMMYFUNCTION("""COMPUTED_VALUE"""),1.0) -> 1 | T25: =IFERROR(__xludf.DUMMYFUNCTION("""COMPUTED_VALUE"""),4.0) -> 4 | U25: =IFERROR(__xludf.DUMMYFUNCTION("""COMPUTED_VALUE"""),4.0) -> 4
B26: 46023 | C26: CONSUMIDOR FINAL | D26: Caramelos Bianchi | E26: {=IF(D26="","",XLOOKUP(D26,DATOS!$D$6:D14000,DATOS!$C$6:C14000,0,0,1))} -> CARM2 | F26: 10 | G26: 0.1 | H26: =IF(F26="","",(F26*G26)) -> 1 | K26: =IF(I26="","",(F26*I26)) | L26: =IF(I26="",H26,H26+(K26/J26)) -> 1 | O26: =IFERROR(__xludf.DUMMYFUNCTION("""COMPUTED_VALUE"""),46024.0) -> 46024 | P26: =IFERROR(__xludf.DUMMYFUNCTION("""COMPUTED_VALUE"""),"CONSUMIDOR FINAL") -> CONSUMIDOR FINAL | Q26: =IFERROR(__xludf.DUMMYFUNCTION("""COMPUTED_VALUE"""),"Panelada 29gr") -> Panelada 29gr | R26: =IFERROR(__xludf.DUMMYFUNCTION("""COMPUTED_VALUE"""),"PANEL") -> PANEL | S26: =IFERROR(__xludf.DUMMYFUNCTION("""COMPUTED_VALUE"""),2.0) -> 2 | T26: =IFERROR(__xludf.DUMMYFUNCTION("""COMPUTED_VALUE"""),1.0) -> 1 | U26: =IFERROR(__xludf.DUMMYFUNCTION("""COMPUTED_VALUE"""),2.0) -> 2
B27: 46023 | C27: CONSUMIDOR FINAL | D27: FLIPS 28G | E27: {=IF(D27="","",XLOOKUP(D27,DATOS!$D$6:D14000,DATOS!$C$6:C14000,0,0,1))} -> FLIP | F27: 2 | G27: 1 | H27: =IF(F27="","",(F27*G27)) -> 2 | K27: =IF(I27="","",(F27*I27)) | L27: =IF(I27="",H27,H27+(K27/J27)) -> 2 | O27: =IFERROR(__xludf.DUMMYFUNCTION("""COMPUTED_VALUE"""),46024.0) -> 46024 | P27: =IFERROR(__xludf.DUMMYFUNCTION("""COMPUTED_VALUE"""),"CONSUMIDOR FINAL") -> CONSUMIDOR FINAL | Q27: =IFERROR(__xludf.DUMMYFUNCTION("""COMPUTED_VALUE"""),"galleta marilu chocolate") -> galleta marilu chocolate | R27: =IFERROR(__xludf.DUMMYFUNCTION("""COMPUTED_VALUE"""),"00017") -> 00017 | S27: =IFERROR(__xludf.DUMMYFUNCTION("""COMPUTED_VALUE"""),2.0) -> 2 | T27: =IFERROR(__xludf.DUMMYFUNCTION("""COMPUTED_VALUE"""),0.5) -> 0.5 | U27: =IFERROR(__xludf.DUMMYFUNCTION("""COMPUTED_VALUE"""),1.0) -> 1
B28: 46023 | C28: CONSUMIDOR FINAL | D28: Caramelos Bianchi | E28: {=IF(D28="","",XLOOKUP(D28,DATOS!$D$6:D14000,DATOS!$C$6:C14000,0,0,1))} -> CARM2 | F28: 10 | G28: 0.1 | H28: =IF(F28="","",(F28*G28)) -> 1 | K28: =IF(I28="","",(F28*I28)) | L28: =IF(I28="",H28,H28+(K28/J28)) -> 1 | O28: =IFERROR(__xludf.DUMMYFUNCTION("""COMPUTED_VALUE"""),46024.0) -> 46024 | P28: =IFERROR(__xludf.DUMMYFUNCTION("""COMPUTED_VALUE"""),"CONSUMIDOR FINAL") -> CONSUMIDOR FINAL | Q28: =IFERROR(__xludf.DUMMYFUNCTION("""COMPUTED_VALUE"""),"PAÑALES TALLA G BABY FINGER 18UND") -> PAÑALES TALLA G BABY FINGER 18UND | R28: =IFERROR(__xludf.DUMMYFUNCTION("""COMPUTED_VALUE"""),"00082") -> 00082 | S28: =IFERROR(__xludf.DUMMYFUNCTION("""COMPUTED_VALUE"""),2.0) -> 2 | T28: =IFERROR(__xludf.DUMMYFUNCTION("""COMPUTED_VALUE"""),0.5) -> 0.5 | U28: =IFERROR(__xludf.DUMMYFUNCTION("""COMPUTED_VALUE"""),1.0) -> 1
B29: 46023 | C29: CONSUMIDOR FINAL | D29: CHOCOLATE BIANCHI DOBLE CHOCOLATE | E29: {=IF(D29="","",XLOOKUP(D29,DATOS!$D$6:D14000,DATOS!$C$6:C14000,0,0,1))} -> 00087 | F29: 2 | G29: 1 | H29: =IF(F29="","",(F29*G29)) -> 2 | K29: =IF(I29="","",(F29*I29)) | L29: =IF(I29="",H29,H29+(K29/J29)) -> 2 | O29: =IFERROR(__xludf.DUMMYFUNCTION("""COMPUTED_VALUE"""),46024.0) -> 46024 | P29: =IFERROR(__xludf.DUMMYFUNCTION("""COMPUTED_VALUE"""),"CONSUMIDOR FINAL") -> CONSUMIDOR FINAL | Q29: =IFERROR(__xludf.DUMMYFUNCTION("""COMPUTED_VALUE"""),"Refrescos 2lt ") -> Refrescos 2lt | R29: =IFERROR(__xludf.DUMMYFUNCTION("""COMPUTED_VALUE"""),"REF4") -> REF4 | S29: =IFERROR(__xludf.DUMMYFUNCTION("""COMPUTED_VALUE"""),1.0) -> 1 | T29: =IFERROR(__xludf.DUMMYFUNCTION("""COMPUTED_VALUE"""),6.0) -> 6 | U29: =IFERROR(__xludf.DUMMYFUNCTION("""COMPUTED_VALUE"""),6.0) -> 6
B30: 46023 | C30: CONSUMIDOR FINAL | D30: PIAZZA BARQUILLAS | E30: {=IF(D30="","",XLOOKUP(D30,DATOS!$D$6:D14000,DATOS!$C$6:C14000,0,0,1))} -> PIAZ | F30: 2 | G30: 0.5 | H30: =IF(F30="","",(F30*G30)) -> 1 | K30: =IF(I30="","",(F30*I30)) | L30: =IF(I30="",H30,H30+(K30/J30)) -> 1 | O30: =IFERROR(__xludf.DUMMYFUNCTION("""COMPUTED_VALUE"""),46024.0) -> 46024 | P30: =IFERROR(__xludf.DUMMYFUNCTION("""COMPUTED_VALUE"""),"CONSUMIDOR FINAL") -> CONSUMIDOR FINAL | Q30: =IFERROR(__xludf.DUMMYFUNCTION("""COMPUTED_VALUE"""),"Jabon las llaves floral (200gr)") -> Jabon las llaves floral (200gr) | R30: =IFERROR(__xludf.DUMMYFUNCTION("""COMPUTED_VALUE"""),"00029") -> 00029 | S30: =IFERROR(__xludf.DUMMYFUNCTION("""COMPUTED_VALUE"""),2.0) -> 2 | T30: =IFERROR(__xludf.DUMMYFUNCTION("""COMPUTED_VALUE"""),2.0) -> 2 | U30: =IFERROR(__xludf.DUMMYFUNCTION("""COMPUTED_VALUE"""),4.0) -> 4
B31: 46023 | C31: CONSUMIDOR FINAL | D31: GALLETA MARILU CHOCOVAINILLA | E31: {=IF(D31="","",XLOOKUP(D31,DATOS!$D$6:D14000,DATOS!$C$6:C14000,0,0,1))} -> GALL024 | F31: 2 | G31: 0.5 | H31: =IF(F31="","",(F31*G31)) -> 1 | K31: =IF(I31="","",(F31*I31)) | L31: =IF(I31="",H31,H31+(K31/J31)) -> 1 | O31: =IFERROR(__xludf.DUMMYFUNCTION("""COMPUTED_VALUE"""),46024.0) -> 46024 | P31: =IFERROR(__xludf.DUMMYFUNCTION("""COMPUTED_VALUE"""),"CONSUMIDOR FINAL") -> CONSUMIDOR FINAL | Q31: =IFERROR(__xludf.DUMMYFUNCTION("""COMPUTED_VALUE"""),"ACEITE LA PAMPA 700ML ") -> ACEITE LA PAMPA 700ML | R31: =IFERROR(__xludf.DUMMYFUNCTION("""COMPUTED_VALUE"""),"00084") -> 00084 | S31: =IFERROR(__xludf.DUMMYFUNCTION("""COMPUTED_VALUE"""),1.0) -> 1 | T31: =IFERROR(__xludf.DUMMYFUNCTION("""COMPUTED_VALUE"""),4.0) -> 4 | U31: =IFERROR(__xludf.DUMMYFUNCTION("""COMPUTED_VALUE"""),4.0) -> 4
B32: 46023 | C32: CONSUMIDOR FINAL | D32: Pollo 1kg | E32: {=IF(D32="","",XLOOKUP(D32,DATOS!$D$6:D14000,DATOS!$C$6:C14000,0,0,1))} -> POLLO | F32: 3.05 | G32: 5 | H32: =IF(F32="","",(F32*G32)) -> 15.25 | K32: =IF(I32="","",(F32*I32)) | L32: =IF(I32="",H32,H32+(K32/J32)) -> 15.25 | O32: =IFERROR(__xludf.DUMMYFUNCTION("""COMPUTED_VALUE"""),46024.0) -> 46024 | P32: =IFERROR(__xludf.DUMMYFUNCTION("""COMPUTED_VALUE"""),"CONSUMIDOR FINAL") -> CONSUMIDOR FINAL | Q32: =IFERROR(__xludf.DUMMYFUNCTION("""COMPUTED_VALUE"""),"Jabon Popular") -> Jabon Popular | R32: =IFERROR(__xludf.DUMMYFUNCTION("""COMPUTED_VALUE"""),"JAB7") -> JAB7 | S32: =IFERROR(__xludf.DUMMYFUNCTION("""COMPUTED_VALUE"""),1.0) -> 1 | T32: =IFERROR(__xludf.DUMMYFUNCTION("""COMPUTED_VALUE"""),1.5) -> 1.5 | U32: =IFERROR(__xludf.DUMMYFUNCTION("""COMPUTED_VALUE"""),1.5) -> 1.5
B33: 46023 | C33: CONSUMIDOR FINAL | D33: ATUN PEÑERO OLIVA VERDE | E33: {=IF(D33="","",XLOOKUP(D33,DATOS!$D$6:D14000,DATOS!$C$6:C14000,0,0,1))} -> 00116 | F33: 1 | G33: 3.5 | H33: =IF(F33="","",(F33*G33)) -> 3.5 | K33: =IF(I33="","",(F33*I33)) | L33: =IF(I33="",H33,H33+(K33/J33)) -> 3.5 | O33: =IFERROR(__xludf.DUMMYFUNCTION("""COMPUTED_VALUE"""),46024.0) -> 46024 | P33: =IFERROR(__xludf.DUMMYFUNCTION("""COMPUTED_VALUE"""),"CONSUMIDOR FINAL") -> CONSUMIDOR FINAL | Q33: =IFERROR(__xludf.DUMMYFUNCTION("""COMPUTED_VALUE"""),"Galletas Maria") -> Galletas Maria | R33: =IFERROR(__xludf.DUMMYFUNCTION("""COMPUTED_VALUE"""),"GALL22") -> GALL22 | S33: =IFERROR(__xludf.DUMMYFUNCTION("""COMPUTED_VALUE"""),1.0) -> 1 | T33: =IFERROR(__xludf.DUMMYFUNCTION("""COMPUTED_VALUE"""),0.5) -> 0.5 | U33: =IFERROR(__xludf.DUMMYFUNCTION("""COMPUTED_VALUE"""),0.5) -> 0.5
B34: 46023 | C34: CONSUMIDOR FINAL | D34: galleta marilu chocolate | E34: {=IF(D34="","",XLOOKUP(D34,DATOS!$D$6:D14000,DATOS!$C$6:C14000,0,0,1))} -> 00017 | F34: 1 | G34: 0.5 | H34: =IF(F34="","",(F34*G34)) -> 0.5 | K34: =IF(I34="","",(F34*I34)) | L34: =IF(I34="",H34,H34+(K34/J34)) -> 0.5 | O34: =IFERROR(__xludf.DUMMYFUNCTION("""COMPUTED_VALUE"""),46024.0) -> 46024 | P34: =IFERROR(__xludf.DUMMYFUNCTION("""COMPUTED_VALUE"""),"CONSUMIDOR FINAL") -> CONSUMIDOR FINAL | Q34: =IFERROR(__xludf.DUMMYFUNCTION("""COMPUTED_VALUE"""),"Huevo") -> Huevo | R34: =IFERROR(__xludf.DUMMYFUNCTION("""COMPUTED_VALUE"""),"HUEVO") -> HUEVO | S34: =IFERROR(__xludf.DUMMYFUNCTION("""COMPUTED_VALUE"""),9.0) -> 9 | T34: =IFERROR(__xludf.DUMMYFUNCTION("""COMPUTED_VALUE"""),0.33333) -> 0.33333 | U34: =IFERROR(__xludf.DUMMYFUNCTION("""COMPUTED_VALUE"""),2.9999700000000002) -> 2.99997
B35: 46023 | C35: CONSUMIDOR FINAL | D35: Belmont | E35: {=IF(D35="","",XLOOKUP(D35,DATOS!$D$6:D14000,DATOS!$C$6:C14000,0,0,1))} -> BELM | F35: 40 | G35: 0.25 | H35: =IF(F35="","",(F35*G35)) -> 10 | K35: =IF(I35="","",(F35*I35)) | L35: =IF(I35="",H35,H35+(K35/J35)) -> 10 | O35: =IFERROR(__xludf.DUMMYFUNCTION("""COMPUTED_VALUE"""),46024.0) -> 46024 | P35: =IFERROR(__xludf.DUMMYFUNCTION("""COMPUTED_VALUE"""),"CONSUMIDOR FINAL") -> CONSUMIDOR FINAL | Q35: =IFERROR(__xludf.DUMMYFUNCTION("""COMPUTED_VALUE"""),"TORONTO") -> TORONTO | R35: =IFERROR(__xludf.DUMMYFUNCTION("""COMPUTED_VALUE"""),"TORON") -> TORON | S35: =IFERROR(__xludf.DUMMYFUNCTION("""COMPUTED_VALUE"""),1.0) -> 1 | T35: =IFERROR(__xludf.DUMMYFUNCTION("""COMPUTED_VALUE"""),1.0) -> 1 | U35: =IFERROR(__xludf.DUMMYFUNCTION("""COMPUTED_VALUE"""),1.0) -> 1
B36: 46023 | C36: CONSUMIDOR FINAL | D36: Pollo 1kg | E36: {=IF(D36="","",XLOOKUP(D36,DATOS!$D$6:D14000,DATOS!$C$6:C14000,0,0,1))} -> POLLO | F36: 2.45 | G36: 5 | H36: =IF(F36="","",(F36*G36)) -> 12.25 | K36: =IF(I36="","",(F36*I36)) | L36: =IF(I36="",H36,H36+(K36/J36)) -> 12.25 | O36: =IFERROR(__xludf.DUMMYFUNCTION("""COMPUTED_VALUE"""),46024.0) -> 46024 | P36: =IFERROR(__xludf.DUMMYFUNCTION("""COMPUTED_VALUE"""),"CONSUMIDOR FINAL") -> CONSUMIDOR FINAL | Q36: =IFERROR(__xludf.DUMMYFUNCTION("""COMPUTED_VALUE"""),"Refrescos 1,5lt") -> Refrescos 1,5lt | R36: =IFERROR(__xludf.DUMMYFUNCTION("""COMPUTED_VALUE"""),"REF2") -> REF2 | S36: =IFERROR(__xludf.DUMMYFUNCTION("""COMPUTED_VALUE"""),1.0) -> 1 | T36: =IFERROR(__xludf.DUMMYFUNCTION("""COMPUTED_VALUE"""),4.0) -> 4 | U36: =IFERROR(__xludf.DUMMYFUNCTION("""COMPUTED_VALUE"""),4.0) -> 4
B37: 46023 | C37: CONSUMIDOR FINAL | D37: GALLETA MARILU 18 G | E37: {=IF(D37="","",XLOOKUP(D37,DATOS!$D$6:D14000,DATOS!$C$6:C14000,0,0,1))} -> 00049 | F37: 4 | G37: 0.25 | H37: =IF(F37="","",(F37*G37)) -> 1 | K37: =IF(I37="","",(F37*I37)) | L37: =IF(I37="",H37,H37+(K37/J37)) -> 1 | O37: =IFERROR(__xludf.DUMMYFUNCTION("""COMPUTED_VALUE"""),46024.0) -> 46024 | P37: =IFERROR(__xludf.DUMMYFUNCTION("""COMPUTED_VALUE"""),"CONSUMIDOR FINAL") -> CONSUMIDOR FINAL | Q37: =IFERROR(__xludf.DUMMYFUNCTION("""COMPUTED_VALUE"""),"Cubitos") -> Cubitos | R37: =IFERROR(__xludf.DUMMYFUNCTION("""COMPUTED_VALUE"""),"CUBITO1") -> CUBITO1 | S37: =IFERROR(__xludf.DUMMYFUNCTION("""COMPUTED_VALUE"""),2.0) -> 2 | T37: =IFERROR(__xludf.DUMMYFUNCTION("""COMPUTED_VALUE"""),0.5) -> 0.5 | U37: =IFERROR(__xludf.DUMMYFUNCTION("""COMPUTED_VALUE"""),1.0) -> 1
B38: 46023 | C38: CONSUMIDOR FINAL | D38: Huevo | E38: {=IF(D38="","",XLOOKUP(D38,DATOS!$D$6:D14000,DATOS!$C$6:C14000,0,0,1))} -> HUEVO | F38: 6 | G38: 0.333333 | H38: =IF(F38="","",(F38*G38)) -> 1.999998 | K38: =IF(I38="","",(F38*I38)) | L38: =IF(I38="",H38,H38+(K38/J38)) -> 1.999998 | O38: =IFERROR(__xludf.DUMMYFUNCTION("""COMPUTED_VALUE"""),46024.0) -> 46024 | P38: =IFERROR(__xludf.DUMMYFUNCTION("""COMPUTED_VALUE"""),"CONSUMIDOR FINAL") -> CONSUMIDOR FINAL | Q38: =IFERROR(__xludf.DUMMYFUNCTION("""COMPUTED_VALUE"""),"CARAMELOS FRUTICAS 100UND") -> CARAMELOS FRUTICAS 100UND | R38: =IFERROR(__xludf.DUMMYFUNCTION("""COMPUTED_VALUE"""),"CARM005") -> CARM005 | S38: =IFERROR(__xludf.DUMMYFUNCTION("""COMPUTED_VALUE"""),10.0) -> 10 | T38: =IFERROR(__xludf.DUMMYFUNCTION("""COMPUTED_VALUE"""),0.1) -> 0.1 | U38: =IFERROR(__xludf.DUMMYFUNCTION("""COMPUTED_VALUE"""),1.0) -> 1
B39: 46023 | C39: CONSUMIDOR FINAL | D39: Galletas club social | E39: {=IF(D39="","",XLOOKUP(D39,DATOS!$D$6:D14000,DATOS!$C$6:C14000,0,0,1))} -> GALL20 | F39: 12 | G39: 0.5 | H39: =IF(F39="","",(F39*G39)) -> 6 | K39: =IF(I39="","",(F39*I39)) | L39: =IF(I39="",H39,H39+(K39/J39)) -> 6 | O39: =IFERROR(__xludf.DUMMYFUNCTION("""COMPUTED_VALUE"""),46024.0) -> 46024 | P39: =IFERROR(__xludf.DUMMYFUNCTION("""COMPUTED_VALUE"""),"CONSUMIDOR FINAL") -> CONSUMIDOR FINAL | Q39: =IFERROR(__xludf.DUMMYFUNCTION("""COMPUTED_VALUE"""),"Pañal Baby finger XG") -> Pañal Baby finger XG | R39: =IFERROR(__xludf.DUMMYFUNCTION("""COMPUTED_VALUE"""),"PAÑL1") -> PAÑL1 | S39: =IFERROR(__xludf.DUMMYFUNCTION("""COMPUTED_VALUE"""),2.0) -> 2 | T39: =IFERROR(__xludf.DUMMYFUNCTION("""COMPUTED_VALUE"""),0.5) -> 0.5 | U39: =IFERROR(__xludf.DUMMYFUNCTION("""COMPUTED_VALUE"""),1.0) -> 1
B40: 46023 | C40: CONSUMIDOR FINAL | D40: DIABLITO 54G | E40: {=IF(D40="","",XLOOKUP(D40,DATOS!$D$6:D14000,DATOS!$C$6:C14000,0,0,1))} -> DIABLI | F40: 2 | G40: 2 | H40: =IF(F40="","",(F40*G40)) -> 4 | K40: =IF(I40="","",(F40*I40)) | L40: =IF(I40="",H40,H40+(K40/J40)) -> 4 | O40: =IFERROR(__xludf.DUMMYFUNCTION("""COMPUTED_VALUE"""),46024.0) -> 46024 | P40: =IFERROR(__xludf.DUMMYFUNCTION("""COMPUTED_VALUE"""),"CONSUMIDOR FINAL") -> CONSUMIDOR FINAL | Q40: =IFERROR(__xludf.DUMMYFUNCTION("""COMPUTED_VALUE"""),"Refrescos 2lt ") -> Refrescos 2lt | R40: =IFERROR(__xludf.DUMMYFUNCTION("""COMPUTED_VALUE"""),"REF4") -> REF4 | S40: =IFERROR(__xludf.DUMMYFUNCTION("""COMPUTED_VALUE"""),1.0) -> 1 | T40: =IFERROR(__xludf.DUMMYFUNCTION("""COMPUTED_VALUE"""),6.0) -> 6 | U40: =IFERROR(__xludf.DUMMYFUNCTION("""COMPUTED_VALUE"""),6.0) -> 6
...

Sheet COMPRAS
C1: BODEGA3 | Y1: BODEGA3
G2: TOTALES | R2: =SUM(R5:R2624) -> 833.11828 | S2: =SUM(S5:S2624) -> 21.9 | X2: FECHA | Y2: PROVEEDOR | Z2: No. COMPROB | AC2: TOTALES | AH2: =SUM(AH5:AH2624) -> 229321.62 | AM2: =SUM(AM5:AM2624) -> 0 | AN2: =SUM(AN5:AN2624) -> 744.18828
G3: =SUM($G$5:$G2624) -> 2486 | I3: COMPRAS EN BOLIVARES | O3: COMPRA EN DOLARES | X3: 46028 | Y3: INVERSIONES DOBLE PICA, C.A. | Z3: 237136 | AC3: =SUM($AC$5:$AC2624) -> 1746 | AD3: COMPRAS EN BOLIVARES | AJ3: COMPRA EN DOLARES
B4: FECHA | C4: PROVEEDOR | D4: No. COMPROB | E4: PRODUCTO | F4: COD/PROD | G4: CANT | H4: CANT/BTO | I4: PRECIO/UNIT | J4: (I/E) | K4: PREC/UNIT/IVA | L4: MONTO/TOT/FACT | M4: TASA | N4: PRECIO/UNIT/$ | O4: PRECIO/UNIT/$ | P4: (I/E) | Q4: PREC/UNIT/IVA | R4: MONTO/TOT/FACT/$ | S4: FLETE | T4: PREC/UNIT/IVA/FLETE | V4: PROB | X4: FECHA | Y4: PROVEEDOR | Z4: No. COMPROB | AA4: PRODUCTO | AB4: COD/PROD | AC4: CANT | AD4: CANT/BTO | AE4: PRECIO/UNIT | AF4: (I/E) | AG4: PREC/UNIT/IVA | AH4: MONTO/TOT/FACT | AI4: TASA | AJ4: PRECIO/UNIT/$ | AK4: PRECIO/UNIT/$ | AL4: (I/E) | AM4: PREC/UNIT/IVA | AN4: MONTO/TOT/FACT/$ | AO4: FLETE | AP4: PREC/UNIT/IVA/FLETE
B5: 46028 | C5: INVERSIONES DOBLE PICA, C.A. | D5: 237136 | E5: ATUN PEÑERO OLIVA VERDE | F5: {=IF(E5="","",XLOOKUP(E5,DATOS!$D$6:$D2624,DATOS!$C$6:$C2624,0,0,1))} -> 00116 | G5: 12 | H5: 12 | I5: =8505.08/G5 -> 708.75667 | J5: E | K5: =IF(I5="","", IF(J5="E",I5,I5*1.16)) -> 708.75667 | L5: =IF(I5="","",G5*K5) -> 8505.08 | M5: 308.15 | N5: =IF(M5="","",K5/M5) -> 2.3000379 | Q5: =IF(O5="","", IF(P5="E",O5,O5*1.16)) | R5: =IF(G5="","",(G5*Q5))+IF(G5="","",(G5*N5)) -> 27.600454 | S5: {=XLOOKUP(E5,PESOS!$B$2:$B2624,PESOS!$F$2:$F2624,"")} | T5: =IF(B5="","",N5+Q5+S5) -> 2.3000379 | V5: =IF(M5="","",(L5/M5)) -> 27.600454 | X5: =IFERROR(__xludf.DUMMYFUNCTION("FILTER(B5:T2624,B5:B2624=X3,C5:C2624=Y3,D5:D2624=Z3)"),46028.0) -> 46028 | Y5: =IFERROR(__xludf.DUMMYFUNCTION("""COMPUTED_VALUE"""),"INVERSIONES DOBLE PICA, C.A.") -> INVERSIONES DOBLE PICA, C.A. | Z5: =IFERROR(__xludf.DUMMYFUNCTION("""COMPUTED_VALUE"""),237136.0) -> 237136 | AA5: =IFERROR(__xludf.DUMMYFUNCTION("""COMPUTED_VALUE"""),"ATUN PEÑERO OLIVA VERDE") -> ATUN PEÑERO OLIVA VERDE | AB5: =IFERROR(__xludf.DUMMYFUNCTION("""COMPUTED_VALUE"""),"00116") -> 00116 | AC5: =IFERROR(__xludf.DUMMYFUNCTION("""COMPUTED_VALUE"""),12.0) -> 12 | AD5: =IFERROR(__xludf.DUMMYFUNCTION("""COMPUTED_VALUE"""),12.0) -> 12 | AE5: =IFERROR(__xludf.DUMMYFUNCTION("""COMPUTED_VALUE"""),708.7566666666667) -> 708.75667 | AF5: =IFERROR(__xludf.DUMMYFUNCTION("""COMPUTED_VALUE"""),"E") -> E | AG5: =IFERROR(__xludf.DUMMYFUNCTION("""COMPUTED_VALUE"""),708.7566666666667) -> 708.75667 | AH5: =IFERROR(__xludf.DUMMYFUNCTION("""COMPUTED_VALUE"""),8505.08) -> 8505.08 | AI5: =IFERROR(__xludf.DUMMYFUNCTION("""COMPUTED_VALUE"""),308.15) -> 308.15 | AJ5: =IFERROR(__xludf.DUMMYFUNCTION("""COMPUTED_VALUE"""),2.300037860349397) -> 2.3000379 | AM5: =IFERROR(__xludf.DUMMYFUNCTION("""COMPUTED_VALUE"""),"") | AN5: =IFERROR(__xludf.DUMMYFUNCTION("""COMPUTED_VALUE"""),27.600454324192768) -> 27.600454 | AO5: =IFERROR(__xludf.DUMMYFUNCTION("""COMPUTED_VALUE"""),"") | AP5: =IFERROR(__xludf.DUMMYFUNCTION("""COMPUTED_VALUE"""),2.300037860349397) -> 2.3000379
B6: 46028 | C6: INVERSIONES DOBLE PICA, C.A. | D6: 237136 | E6: Pañal Baby finger XG | F6: {=IF(E6="","",XLOOKUP(E6,DATOS!$D$6:$D2624,DATOS!$C$6:$C2624,0,0,1))} -> PAÑL1 | G6: 192 | H6: 192 | I6: =17745.48/G6 -> 92.424375 | J6: E | K6: =IF(I6="","", IF(J6="E",I6,I6*1.16)) -> 92.424375 | L6: =IF(I6="","",G6*K6) -> 17745.48 | M6: 308.15 | N6: =IF(M6="","",K6/M6) -> 0.29993307 | Q6: =IF(O6="","", IF(P6="E",O6,O6*1.16)) | R6: =IF(G6="","",(G6*Q6))+IF(G6="","",(G6*N6)) -> 57.587149 | S6: {=XLOOKUP(E6,PESOS!$B$2:$B2624,PESOS!$F$2:$F2624,"")} | T6: =IF(B6="","",N6+Q6+S6) -> 0.29993307 | V6: =IF(M6="","",(L6/M6)) -> 57.587149 | X6: =IFERROR(__xludf.DUMMYFUNCTION("""COMPUTED_VALUE"""),46028.0) -> 46028 | Y6: =IFERROR(__xludf.DUMMYFUNCTION("""COMPUTED_VALUE"""),"INVERSIONES DOBLE PICA, C.A.") -> INVERSIONES DOBLE PICA, C.A. | Z6: =IFERROR(__xludf.DUMMYFUNCTION("""COMPUTED_VALUE"""),237136.0) -> 237136 | AA6: =IFERROR(__xludf.DUMMYFUNCTION("""COMPUTED_VALUE"""),"Pañal Baby finger XG") -> Pañal Baby finger XG | AB6: =IFERROR(__xludf.DUMMYFUNCTION("""COMPUTED_VALUE"""),"PAÑL1") -> PAÑL1 | AC6: =IFERROR(__xludf.DUMMYFUNCTION("""COMPUTED_VALUE"""),192.0) -> 192 | AD6: =IFERROR(__xludf.DUMMYFUNCTION("""COMPUTED_VALUE"""),192.0) -> 192 | AE6: =IFERROR(__xludf.DUMMYFUNCTION("""COMPUTED_VALUE"""),92.424375) -> 92.424375 | AF6: =IFERROR(__xludf.DUMMYFUNCTION("""COMPUTED_VALUE"""),"E") -> E | AG6: =IFERROR(__xludf.DUMMYFUNCTION("""COMPUTED_VALUE"""),92.424375) -> 92.424375 | AH6: =IFERROR(__xludf.DUMMYFUNCTION("""COMPUTED_VALUE"""),17745.48) -> 17745.48 | AI6: =IFERROR(__xludf.DUMMYFUNCTION("""COMPUTED_VALUE"""),308.15) -> 308.15 | AJ6: =IFERROR(__xludf.DUMMYFUNCTION("""COMPUTED_VALUE"""),0.29993306831088756) -> 0.29993307 | AM6: =IFERROR(__xludf.DUMMYFUNCTION("""COMPUTED_VALUE"""),"") | AN6: =IFERROR(__xludf.DUMMYFUNCTION("""COMPUTED_VALUE"""),57.58714911569041) -> 57.587149 | AO6: =IFERROR(__xludf.DUMMYFUNCTION("""COMPUTED_VALUE"""),"") | AP6: =IFERROR(__xludf.DUMMYFUNCTION("""COMPUTED_VALUE"""),0.29993306831088756) -> 0.29993307
B7: 46028 | C7: INVERSIONES DOBLE PICA, C.A. | D7: 237136 | E7: CAFE AMANECER 500GR | F7: {=IF(E7="","",XLOOKUP(E7,DATOS!$D$6:$D2624,DATOS!$C$6:$C2624,0,0,1))} -> 00120 | G7: 10 | H7: 10 | I7: =19382.95/G7 -> 1938.295 | J7: E | K7: =IF(I7="","", IF(J7="E",I7,I7*1.16)) -> 1938.295 | L7: =IF(I7="","",G7*K7) -> 19382.95 | M7: 308.15 | N7: =IF(M7="","",K7/M7) -> 6.2901022 | Q7: =IF(O7="","", IF(P7="E",O7,O7*1.16)) | R7: =IF(G7="","",(G7*Q7))+IF(G7="","",(G7*N7)) -> 62.901022 | S7: {=XLOOKUP(E7,PESOS!$B$2:$B2624,PESOS!$F$2:$F2624,"")} | T7: =IF(B7="","",N7+Q7+S7) -> 6.2901022 | V7: =IF(M7="","",(L7/M7)) -> 62.901022 | X7: =IFERROR(__xludf.DUMMYFUNCTION("""COMPUTED_VALUE"""),46028.0) -> 46028 | Y7: =IFERROR(__xludf.DUMMYFUNCTION("""COMPUTED_VALUE"""),"INVERSIONES DOBLE PICA, C.A.") -> INVERSIONES DOBLE PICA, C.A. | Z7: =IFERROR(__xludf.DUMMYFUNCTION("""COMPUTED_VALUE"""),237136.0) -> 237136 | AA7: =IFERROR(__xludf.DUMMYFUNCTION("""COMPUTED_VALUE"""),"CAFE AMANECER 500GR") -> CAFE AMANECER 500GR | AB7: =IFERROR(__xludf.DUMMYFUNCTION("""COMPUTED_VALUE"""),"00120") -> 00120 | AC7: =IFERROR(__xludf.DUMMYFUNCTION("""COMPUTED_VALUE"""),10.0) -> 10 | AD7: =IFERROR(__xludf.DUMMYFUNCTION("""COMPUTED_VALUE"""),10.0) -> 10 | AE7: =IFERROR(__xludf.DUMMYFUNCTION("""COMPUTED_VALUE"""),1938.295) -> 1938.295 | AF7: =IFERROR(__xludf.DUMMYFUNCTION("""COMPUTED_VALUE"""),"E") -> E | AG7: =IFERROR(__xludf.DUMMYFUNCTION("""COMPUTED_VALUE"""),1938.295) -> 1938.295 | AH7: =IFERROR(__xludf.DUMMYFUNCTION("""COMPUTED_VALUE"""),19382.95) -> 19382.95 | AI7: =IFERROR(__xludf.DUMMYFUNCTION("""COMPUTED_VALUE"""),308.15) -> 308.15 | AJ7: =IFERROR(__xludf.DUMMYFUNCTION("""COMPUTED_VALUE"""),6.290102222943372) -> 6.2901022 | AM7: =IFERROR(__xludf.DUMMYFUNCTION("""COMPUTED_VALUE"""),"") | AN7: =IFERROR(__xludf.DUMMYFUNCTION("""COMPUTED_VALUE"""),62.90102222943372) -> 62.901022 | AO7: =IFERROR(__xludf.DUMMYFUNCTION("""COMPUTED_VALUE"""),"") | AP7: =IFERROR(__xludf.DUMMYFUNCTION("""COMPUTED_VALUE"""),6.290102222943372) -> 6.2901022
B8: 46028 | C8: INVERSIONES DOBLE PICA, C.A. | D8: 237136 | E8: Café Amanecer 200g | F8: {=IF(E8="","",XLOOKUP(E8,DATOS!$D$6:$D2624,DATOS!$C$6:$C2624,0,0,1))} -> CA1 | G8: 24 | H8: 24 | I8: =18366.04/G8 -> 765.25167 | J8: E | K8: =IF(I8="","", IF(J8="E",I8,I8*1.16)) -> 765.25167 | L8: =IF(I8="","",G8*K8) -> 18366.04 | M8: 308.15 | N8: =IF(M8="","",K8/M8) -> 2.4833739 | Q8: =IF(O8="","", IF(P8="E",O8,O8*1.16)) | R8: =IF(G8="","",(G8*Q8))+IF(G8="","",(G8*N8)) -> 59.600974 | S8: {=XLOOKUP(E8,PESOS!$B$2:$B2624,PESOS!$F$2:$F2624,"")} | T8: =IF(B8="","",N8+Q8+S8) -> 2.4833739 | V8: =IF(M8="","",(L8/M8)) -> 59.600974 | X8: =IFERROR(__xludf.DUMMYFUNCTION("""COMPUTED_VALUE"""),46028.0) -> 46028 | Y8: =IFERROR(__xludf.DUMMYFUNCTION("""COMPUTED_VALUE"""),"INVERSIONES DOBLE PICA, C.A.") -> INVERSIONES DOBLE PICA, C.A. | Z8: =IFERROR(__xludf.DUMMYFUNCTION("""COMPUTED_VALUE"""),237136.0) -> 237136 | AA8: =IFERROR(__xludf.DUMMYFUNCTION("""COMPUTED_VALUE"""),"Café Amanecer 200g") -> Café Amanecer 200g | AB8: =IFERROR(__xludf.DUMMYFUNCTION("""COMPUTED_VALUE"""),"CA1") -> CA1 | AC8: =IFERROR(__xludf.DUMMYFUNCTION("""COMPUTED_VALUE"""),24.0) -> 24 | AD8: =IFERROR(__xludf.DUMMYFUNCTION("""COMPUTED_VALUE"""),24.0) -> 24 | AE8: =IFERROR(__xludf.DUMMYFUNCTION("""COMPUTED_VALUE"""),765.2516666666667) -> 765.25167 | AF8: =IFERROR(__xludf.DUMMYFUNCTION("""COMPUTED_VALUE"""),"E") -> E | AG8: =IFERROR(__xludf.DUMMYFUNCTION("""COMPUTED_VALUE"""),765.2516666666667) -> 765.25167 | AH8: =IFERROR(__xludf.DUMMYFUNCTION("""COMPUTED_VALUE"""),18366.04) -> 18366.04 | AI8: =IFERROR(__xludf.DUMMYFUNCTION("""COMPUTED_VALUE"""),308.15) -> 308.15 | AJ8: =IFERROR(__xludf.DUMMYFUNCTION("""COMPUTED_VALUE"""),2.4833738979934017) -> 2.4833739 | AM8: =IFERROR(__xludf.DUMMYFUNCTION("""COMPUTED_VALUE"""),"") | AN8: =IFERROR(__xludf.DUMMYFUNCTION("""COMPUTED_VALUE"""),59.60097355184164) -> 59.600974 | AO8: =IFERROR(__xludf.DUMMYFUNCTION("""COMPUTED_VALUE"""),"") | AP8: =IFERROR(__xludf.DUMMYFUNCTION("""COMPUTED_VALUE"""),2.4833738979934017) -> 2.4833739
B9: 46028 | C9: INVERSIONES DOBLE PICA, C.A. | D9: 237136 | E9: Belmont | F9: {=IF(E9="","",XLOOKUP(E9,DATOS!$D$6:$D2624,DATOS!$C$6:$C2624,0,0,1))} -> BELM | G9: 1000 | H9: 200 | I9: =39906.07/G9 -> 39.90607 | J9: E | K9: =IF(I9="","", IF(J9="E",I9,I9*1.16)) -> 39.90607 | L9: =IF(I9="","",G9*K9) -> 39906.07 | M9: 308.15 | N9: =IF(M9="","",K9/M9) -> 0.12950209 | Q9: =IF(O9="","", IF(P9="E",O9,O9*1.16)) | R9: =IF(G9="","",(G9*Q9))+IF(G9="","",(G9*N9)) -> 129.50209 | S9: {=XLOOKUP(E9,PESOS!$B$2:$B2624,PESOS!$F$2:$F2624,"")} | T9: =IF(B9="","",N9+Q9+S9) -> 0.12950209 | V9: =IF(M9="","",(L9/M9)) -> 129.50209 | X9: =IFERROR(__xludf.DUMMYFUNCTION("""COMPUTED_VALUE"""),46028.0) -> 46028 | Y9: =IFERROR(__xludf.DUMMYFUNCTION("""COMPUTED_VALUE"""),"INVERSIONES DOBLE PICA, C.A.") -> INVERSIONES DOBLE PICA, C.A. | Z9: =IFERROR(__xludf.DUMMYFUNCTION("""COMPUTED_VALUE"""),237136.0) -> 237136 | AA9: =IFERROR(__xludf.DUMMYFUNCTION("""COMPUTED_VALUE"""),"Belmont") -> Belmont | AB9: =IFERROR(__xludf.DUMMYFUNCTION("""COMPUTED_VALUE"""),"BELM") -> BELM | AC9: =IFERROR(__xludf.DUMMYFUNCTION("""COMPUTED_VALUE"""),1000.0) -> 1000 | AD9: =IFERROR(__xludf.DUMMYFUNCTION("""COMPUTED_VALUE"""),200.0) -> 200 | AE9: =IFERROR(__xludf.DUMMYFUNCTION("""COMPUTED_VALUE"""),39.90607) -> 39.90607 | AF9: =IFERROR(__xludf.DUMMYFUNCTION("""COMPUTED_VALUE"""),"E") -> E | AG9: =IFERROR(__xludf.DUMMYFUNCTION("""COMPUTED_VALUE"""),39.90607) -> 39.90607 | AH9: =IFERROR(__xludf.DUMMYFUNCTION("""COMPUTED_VALUE"""),39906.07) -> 39906.07 | AI9: =IFERROR(__xludf.DUMMYFUNCTION("""COMPUTED_VALUE"""),308.15) -> 308.15 | AJ9: =IFERROR(__xludf.DUMMYFUNCTION("""COMPUTED_VALUE"""),0.12950209313645952) -> 0.12950209 | AM9: =IFERROR(__xludf.DUMMYFUNCTION("""COMPUTED_VALUE"""),"") | AN9: =IFERROR(__xludf.DUMMYFUNCTION("""COMPUTED_VALUE"""),129.50209313645954) -> 129.50209 | AO9: =IFERROR(__xludf.DUMMYFUNCTION("""COMPUTED_VALUE"""),"") | AP9: =IFERROR(__xludf.DUMMYFUNCTION("""COMPUTED_VALUE"""),0.12950209313645952) -> 0.12950209
B10: 46028 | C10: INVERSIONES DOBLE PICA, C.A. | D10: 237136 | E10: Cubitos | F10: {=IF(E10="","",XLOOKUP(E10,DATOS!$D$6:$D2624,DATOS!$C$6:$C2624,0,0,1))} -> CUBITO1 | G10: 250 | H10: 250 | I10: =12087.11/G10 -> 48.34844 | J10: G | K10: =IF(I10="","", IF(J10="E",I10,I10*1.16)) -> 56.08419 | L10: =IF(I10="","",G10*K10) -> 14021.048 | M10: 308.15 | N10: =IF(M10="","",K10/M10) -> 0.18200289 | Q10: =IF(O10="","", IF(P10="E",O10,O10*1.16)) | R10: =IF(G10="","",(G10*Q10))+IF(G10="","",(G10*N10)) -> 45.500722 | S10: {=XLOOKUP(E10,PESOS!$B$2:$B2624,PESOS!$F$2:$F2624,"")} | T10: =IF(B10="","",N10+Q10+S10) -> 0.18200289 | V10: =IF(M10="","",(L10/M10)) -> 45.500722 | X10: =IFERROR(__xludf.DUMMYFUNCTION("""COMPUTED_VALUE"""),46028.0) -> 46028 | Y10: =IFERROR(__xludf.DUMMYFUNCTION("""COMPUTED_VALUE"""),"INVERSIONES DOBLE PICA, C.A.") -> INVERSIONES DOBLE PICA, C.A. | Z10: =IFERROR(__xludf.DUMMYFUNCTION("""COMPUTED_VALUE"""),237136.0) -> 237136 | AA10: =IFERROR(__xludf.DUMMYFUNCTION("""COMPUTED_VALUE"""),"Cubitos") -> Cubitos | AB10: =IFERROR(__xludf.DUMMYFUNCTION("""COMPUTED_VALUE"""),"CUBITO1") -> CUBITO1 | AC10: =IFERROR(__xludf.DUMMYFUNCTION("""COMPUTED_VALUE"""),250.0) -> 250 | AD10: =IFERROR(__xludf.DUMMYFUNCTION("""COMPUTED_VALUE"""),250.0) -> 250 | AE10: =IFERROR(__xludf.DUMMYFUNCTION("""COMPUTED_VALUE"""),48.348440000000004) -> 48.34844 | AF10: =IFERROR(__xludf.DUMMYFUNCTION("""COMPUTED_VALUE"""),"G") -> G | AG10: =IFERROR(__xludf.DUMMYFUNCTION("""COMPUTED_VALUE"""),56.0841904) -> 56.08419 | AH10: =IFERROR(__xludf.DUMMYFUNCTION("""COMPUTED_VALUE"""),14021.0476) -> 14021.048 | AI10: =IFERROR(__xludf.DUMMYFUNCTION("""COMPUTED_VALUE"""),308.15) -> 308.15 | AJ10: =IFERROR(__xludf.DUMMYFUNCTION("""COMPUTED_VALUE"""),0.18200288950186597) -> 0.18200289 | AM10: =IFERROR(__xludf.DUMMYFUNCTION("""COMPUTED_VALUE"""),"") | AN10: =IFERROR(__xludf.DUMMYFUNCTION("""COMPUTED_VALUE"""),45.500722375466495) -> 45.500722 | AO10: =IFERROR(__xludf.DUMMYFUNCTION("""COMPUTED_VALUE"""),"") | AP10: =IFERROR(__xludf.DUMMYFUNCTION("""COMPUTED_VALUE"""),0.18200288950186597) -> 0.18200289
B11: 46028 | C11: INVERSIONES DOBLE PICA, C.A. | D11: 237136 | E11: alive/detergente c/suavisante 1kg | F11: {=IF(E11="","",XLOOKUP(E11,DATOS!$D$6:$D2624,DATOS!$C$6:$C2624,0,0,1))} -> 00002 | G11: 24 | H11: 12 | I11: =17958/G11 -> 748.25 | J11: G | K11: =IF(I11="","", IF(J11="E",I11,I11*1.16)) -> 867.97 | L11: =IF(I11="","",G11*K11) -> 20831.28 | M11: 308.15 | N11: =IF(M11="","",K11/M11) -> 2.8167126 | Q11: =IF(O11="","", IF(P11="E",O11,O11*1.16)) | R11: =IF(G11="","",(G11*Q11))+IF(G11="","",(G11*N11)) -> 67.601103 | S11: {=XLOOKUP(E11,PESOS!$B$2:$B2624,PESOS!$F$2:$F2624,"")} | T11: =IF(B11="","",N11+Q11+S11) -> 2.8167126 | V11: =IF(M11="","",(L11/M11)) -> 67.601103 | X11: =IFERROR(__xludf.DUMMYFUNCTION("""COMPUTED_VALUE"""),46028.0) -> 46028 | Y11: =IFERROR(__xludf.DUMMYFUNCTION("""COMPUTED_VALUE"""),"INVERSIONES DOBLE PICA, C.A.") -> INVERSIONES DOBLE PICA, C.A. | Z11: =IFERROR(__xludf.DUMMYFUNCTION("""COMPUTED_VALUE"""),237136.0) -> 237136 | AA11: =IFERROR(__xludf.DUMMYFUNCTION("""COMPUTED_VALUE"""),"alive/detergente c/suavisante 1kg") -> alive/detergente c/suavisante 1kg | AB11: =IFERROR(__xludf.DUMMYFUNCTION("""COMPUTED_VALUE"""),"00002 ") -> 00002 | AC11: =IFERROR(__xludf.DUMMYFUNCTION("""COMPUTED_VALUE"""),24.0) -> 24 | AD11: =IFERROR(__xludf.DUMMYFUNCTION("""COMPUTED_VALUE"""),12.0) -> 12 | AE11: =IFERROR(__xludf.DUMMYFUNCTION("""COMPUTED_VALUE"""),748.25) -> 748.25 | AF11: =IFERROR(__xludf.DUMMYFUNCTION("""COMPUTED_VALUE"""),"G") -> G | AG11: =IFERROR(__xludf.DUMMYFUNCTION("""COMPUTED_VALUE"""),867.9699999999999) -> 867.97 | AH11: =IFERROR(__xludf.DUMMYFUNCTION("""COMPUTED_VALUE"""),20831.28) -> 20831.28 | AI11: =IFERROR(__xludf.DUMMYFUNCTION("""COMPUTED_VALUE"""),308.15) -> 308.15 | AJ11: =IFERROR(__xludf.DUMMYFUNCTION("""COMPUTED_VALUE"""),2.816712639948077) -> 2.8167126 | AM11: =IFERROR(__xludf.DUMMYFUNCTION("""COMPUTED_VALUE"""),"") | AN11: =IFERROR(__xludf.DUMMYFUNCTION("""COMPUTED_VALUE"""),67.60110335875385) -> 67.601103 | AO11: =IFERROR(__xludf.DUMMYFUNCTION("""COMPUTED_VALUE"""),"") | AP11: =IFERROR(__xludf.DUMMYFUNCTION("""COMPUTED_VALUE"""),2.816712639948077) -> 2.8167126
